<?xml version="1.0" ?>
<!-- =================================================================================== -->
<!-- |    This document was autogenerated by xacro from master_assembly.xacro          | -->
<!-- |    EDITING THIS FILE BY HAND IS NOT RECOMMENDED                                 | -->
<!-- =================================================================================== -->
<robot name="RevEx_Full_Assembly">
  <material name="Grey">
    <color rgba="0.6 0.6 0.6 1.0"/>
  </material>
  <material name="DarkGrey">
    <color rgba="0.22 0.22 0.22 1.0"/>
  </material>
  <material name="LightGrey">
    <color rgba="0.8 0.8 0.8 1.0"/>
  </material>
  <link name="base_link"/>
  <joint name="base_joint" type="fixed">
    <parent link="base_link"/>
    <child link="pelvis_link"/>
    <origin rpy="0 0 0" xyz="0 0 0.24515"/>
  </joint>
  <link name="pelvis_link">
    <inertial>
      <origin rpy="0 0 0" xyz="-0.0540918323179141 -3.48259522403486E-05 -0.0156255182184312"/>
      <mass value="3.50691251175897"/>
      <inertia ixx="0.00552189690363016" ixy="4.55841164433384E-06" ixz="-7.80273388403568E-05" iyy="0.00626668820315558" iyz="1.10177467151231E-07" izz="0.00504655399919599"/>
    </inertial>
    <visual>
      <origin rpy="0 0 0" xyz="0 0 0"/>
      <geometry>
        <mesh filename="C:/Projects/RevExBot/RevEx_Phase1_Hardware/mechanical/meshes/IMU_ORIGIN.STL"/>
      </geometry>
      <material name="Grey"/>
    </visual>
    <collision name="pelvis_collision">
      <origin rpy="0 0 0" xyz="-0.04 0 -0.0125"/>
      <geometry>
        <box size="0.08 0.08 0.075"/>
      </geometry>
    </collision>
  </link>
  <link name="left_hip_pitch_link">
    <inertial>
      <origin rpy="0 0 0" xyz="0.00172895433511948 0.0360563262466087 0.000569266739481308"/>
      <mass value="1.05630112217695"/>
      <inertia ixx="0.00069232989080039" ixy="-3.57661961446218E-05" ixz="1.84003368216204E-06" iyy="0.000812587075023366" iyz="1.2003147635279E-05" izz="0.000753380131267806"/>
    </inertial>
    <visual>
      <geometry>
        <mesh filename="C:/Projects/RevExBot/RevEx_Phase1_Hardware/mechanical/meshes/LEFT_HIP_PITCH.STL"/>
      </geometry>
      <material name="Grey"/>
    </visual>
    <collision name="left_hip_pitch_collision">
      <origin rpy="0 0 0" xyz="0 0.03 0"/>
      <geometry>
        <cylinder length="0.04" radius="0.04"/>
      </geometry>
    </collision>
  </link>
  <joint name="left_hip_pitch_joint" type="revolute">
    <origin rpy="0 0 0" xyz="-0.052 0.0675 -0.044045"/>
    <parent link="pelvis_link"/>
    <child link="left_hip_pitch_link"/>
    <axis xyz="0 1 0"/>
    <limit effort="180.0" lower="-2.094" upper="1.047" velocity="8"/>
    <dynamics damping="0.095625" friction="0"/>
  </joint>
  <link name="left_hip_roll_link">
    <inertial>
      <origin rpy="0 0 0" xyz="-0.0115541390699202 -0.000334827946236529 -0.0294101852668513"/>
      <mass value="0.414368139397033"/>
      <inertia ixx="0.000265394006141893" ixy="2.21514388143389E-06" ixz="-0.000115781041690773" iyy="0.000357453871035062" iyz="2.9843892878895E-06" izz="0.000234474271498986"/>
    </inertial>
    <visual>
      <geometry>
        <mesh filename="C:/Projects/RevExBot/RevEx_Phase1_Hardware/mechanical/meshes/LEFT_HIP_ROLL.STL"/>
      </geometry>
      <material name="Grey"/>
    </visual>
  </link>
  <joint name="left_hip_roll_joint" type="revolute">
    <origin rpy="0 0 0" xyz="0.0422501 0.0400002759400924 0"/>
    <parent link="left_hip_pitch_link"/>
    <child link="left_hip_roll_link"/>
    <axis xyz="1 0 0"/>
    <limit effort="150.0" lower="-0.698" upper="0.698" velocity="8"/>
    <dynamics damping="0.11" friction="0"/>
  </joint>
  <link name="left_hip_yaw_link">
    <inertial>
      <origin rpy="0 0 0" xyz="0.00107948196019631 0.00102490074879569 -0.18050828862704701"/>
      <mass value="2.79985524654237"/>
      <inertia ixx="0.007686738130220505" ixy="1.12872344062739E-05" ixz="2.89779048114687E-05" iyy="0.008010357947331884" iyz="-0.000119761895425219" izz="0.002062865581654875"/>
    </inertial>
    <visual>
      <geometry>
        <mesh filename="C:/Projects/RevExBot/RevEx_Phase1_Hardware/mechanical/meshes/LEFT_HIP_YAW.STL" scale="1 1 1.5"/>
      </geometry>
      <material name="Grey"/>
    </visual>
    <collision name="left_hip_yaw_collision">
      <origin rpy="0 0 0" xyz="0 0 -0.1275"/>
      <geometry>
        <cylinder length="0.10500000000000001" radius="0.04"/>
      </geometry>
    </collision>
  </link>
  <joint name="left_hip_yaw_joint" type="revolute">
    <origin rpy="0 0 0" xyz="-0.0422499999999954 0 -0.0520000000000006"/>
    <parent link="left_hip_roll_link"/>
    <child link="left_hip_yaw_link"/>
    <axis xyz="0 0 -1"/>
    <limit effort="120.0" lower="-0.698" upper="0.698" velocity="8"/>
    <dynamics damping="0.038" friction="0"/>
  </joint>
  <link name="left_knee_link">
    <inertial>
      <origin rpy="0 0 0" xyz="-0.000500664455004187 0.000509289489479564 -0.16903933154118"/>
      <mass value="3.58671226549614"/>
      <inertia ixx="0.02164887135427113" ixy="9.87646392241852E-06" ixz="-0.000645140055016828" iyy="0.02194457302262119" iyz="-7.94058135611557E-06" izz="0.0034964285541001046"/>
    </inertial>
    <visual>
      <geometry>
        <mesh filename="C:/Projects/RevExBot/RevEx_Phase1_Hardware/mechanical/meshes/LEFT_KNEE.STL" scale="1 1 1.5"/>
      </geometry>
      <material name="Grey"/>
    </visual>
    <collision name="left_knee_collision">
      <origin rpy="0 0 0" xyz="0 0 -0.195"/>
      <geometry>
        <cylinder length="0.27" radius="0.04"/>
      </geometry>
    </collision>
  </link>
  <joint name="left_knee_joint" type="revolute">
    <origin rpy="0 0 0" xyz="0 0 -0.293459999999997"/>
    <parent link="left_hip_yaw_link"/>
    <child link="left_knee_link"/>
    <axis xyz="0 1 0"/>
    <limit effort="225.0" lower="0" upper="1.5" velocity="8"/>
    <dynamics damping="0.0339552" friction="0"/>
  </joint>
  <link name="left_ankle_pitch_link">
    <inertial>
      <origin rpy="0 0 0" xyz="-0.00117927040588633 -3.07019113465756E-08 -0.00617619235424882"/>
      <mass value="0.273090119400173"/>
      <inertia ixx="6.4266131977376E-05" ixy="-2.40573155297429E-10" ixz="-1.07534511935557E-06" iyy="8.09944211394154E-05" iyz="-2.30560104829896E-10" izz="4.71927841328634E-05"/>
    </inertial>
    <visual>
      <geometry>
        <mesh filename="C:/Projects/RevExBot/RevEx_Phase1_Hardware/mechanical/meshes/LEFT_ANKLE_A.STL"/>
      </geometry>
      <material name="Grey"/>
    </visual>
  </link>
  <joint name="left_ankle_pitch_joint" type="revolute">
    <origin rpy="0 0 0" xyz="0 0 -0.44199350413053606"/>
    <parent link="left_knee_link"/>
    <child link="left_ankle_pitch_link"/>
    <axis xyz="0 1 0"/>
    <limit effort="120.0" lower="-0.35" upper="0.35" velocity="8"/>
    <dynamics damping="0.0565056" friction="0"/>
  </joint>
  <link name="left_ankle_roll_link">
    <inertial>
      <origin rpy="0 0 0" xyz="0.0427499381311452 0.00159257307585033 -0.013245065948313"/>
      <mass value="0.405640437504617"/>
      <inertia ixx="0.000176487912025914" ixy="1.27462095049061E-05" ixz="-1.32327317762052E-05" iyy="0.000413325911157839" iyz="5.53283535966561E-06" izz="0.000531913025014091"/>
    </inertial>
    <visual>
      <geometry>
        <mesh filename="C:/Projects/RevExBot/RevEx_Phase1_Hardware/mechanical/meshes/LEFT_ANKLE_B.STL"/>
      </geometry>
      <material name="Grey"/>
    </visual>
  </link>
  <joint name="left_ankle_roll_joint" type="revolute">
    <origin rpy="0 0 0" xyz="-0.00149999999999975 0 -0.00999999200000223"/>
    <parent link="left_ankle_pitch_link"/>
    <child link="left_ankle_roll_link"/>
    <axis xyz="-1 0 0"/>
    <limit effort="75.0" lower="-0.1" upper="0.1" velocity="8"/>
    <dynamics damping="0.0565056" friction="0"/>
  </joint>
  <link name="left_toe_link">
    <inertial>
      <origin rpy="0 0 0" xyz="0.0320167773761624 0.000718248511968056 -0.0141312773022902"/>
      <mass value="0.112221237946844"/>
      <inertia ixx="5.5351925218088e-05" ixy="0" ixz="0" iyy="3.65130809524718e-05" iyz="0" izz="8.54029969529202e-05"/>
    </inertial>
    <visual>
      <origin rpy="0 0 0" xyz="0 0.008 0"/>
      <geometry>
        <mesh filename="C:/Projects/RevExBot/RevEx_Phase1_Hardware/mechanical/meshes/LEFT_TOE.STL"/>
      </geometry>
      <material name="DarkGrey"/>
    </visual>
    <collision name="left_toe_collision">
      <origin rpy="0 0 0" xyz="0.025 0 0"/>
      <geometry>
        <box size="0.05 0.06 0.008"/>
      </geometry>
    </collision>
  </link>
  <joint name="left_toe_joint" type="revolute">
    <origin rpy="0 0 0" xyz="0.10253 -0.0043664 -0.0067324"/>
    <parent link="left_ankle_roll_link"/>
    <child link="left_toe_link"/>
    <axis xyz="0.010532 0.99994 0"/>
    <limit effort="45.0" lower="-1.047" upper="0.349" velocity="8"/>
    <dynamics damping="0.001" friction="0.02"/>
  </joint>
  <link name="right_hip_pitch_link">
    <inertial>
      <origin rpy="0 0 0" xyz="0.00172891543963928 -0.0360560777469901 0.000568830845064178"/>
      <mass value="1.05629742879001"/>
      <inertia ixx="0.000692329136191241" ixy="3.57650372725171E-05" ixz="1.84099820196341E-06" iyy="0.00081258255865219" iyz="-1.20075387086281E-05" izz="0.000753384108654712"/>
    </inertial>
    <visual>
      <geometry>
        <mesh filename="C:/Projects/RevExBot/RevEx_Phase1_Hardware/mechanical/meshes/RIGHT_HIP_PITCH.STL"/>
      </geometry>
      <material name="Grey"/>
    </visual>
    <collision name="right_hip_pitch_collision">
      <origin rpy="0 0 0" xyz="0 -0.03 0"/>
      <geometry>
        <cylinder length="0.04" radius="0.04"/>
      </geometry>
    </collision>
  </link>
  <joint name="right_hip_pitch_joint" type="revolute">
    <origin rpy="0 0 0" xyz="-0.0519999999999999 -0.0675 -0.0440449999999999"/>
    <parent link="pelvis_link"/>
    <child link="right_hip_pitch_link"/>
    <axis xyz="0 -1 0"/>
    <limit effort="180.0" lower="-1.047" upper="2.094" velocity="8"/>
    <dynamics damping="0.095625" friction="0"/>
  </joint>
  <link name="right_hip_roll_link">
    <inertial>
      <origin rpy="0 0 0" xyz="-0.0115435673741928 0.000361458713869084 -0.0293858908276063"/>
      <mass value="0.414825000619808"/>
      <inertia ixx="0.000265893227185752" ixy="-2.33135893268163E-06" ixz="-0.000115883966141926" iyy="0.000357734750091647" iyz="-3.23262089994153E-06" izz="0.000234803924170236"/>
    </inertial>
    <visual>
      <geometry>
        <mesh filename="C:/Projects/RevExBot/RevEx_Phase1_Hardware/mechanical/meshes/RIGHT_HIP_ROLL.STL"/>
      </geometry>
      <material name="Grey"/>
    </visual>
  </link>
  <joint name="right_hip_roll_joint" type="revolute">
    <origin rpy="0 0 0" xyz="0.04225 -0.04 0"/>
    <parent link="right_hip_pitch_link"/>
    <child link="right_hip_roll_link"/>
    <axis xyz="1 0 0"/>
    <limit effort="150.0" lower="-0.698" upper="0.698" velocity="8"/>
    <dynamics damping="0.11" friction="0"/>
  </joint>
  <link name="right_hip_yaw_link">
    <inertial>
      <origin rpy="0 0 0" xyz="0.0010759524804974 -0.00102176499629938 -0.180517674041772"/>
      <mass value="2.799708306743505"/>
      <inertia ixx="0.007685746526885242" ixy="-1.17597783272228E-05" ixz="2.91733595327906E-05" iyy="0.008009775347662845" iyz="0.00011971567133214" izz="0.002062879082614005"/>
    </inertial>
    <visual>
      <geometry>
        <mesh filename="C:/Projects/RevExBot/RevEx_Phase1_Hardware/mechanical/meshes/RIGHT_HIP_YAW.STL" scale="1 1 1.5"/>
      </geometry>
      <material name="Grey"/>
    </visual>
    <collision name="right_hip_yaw_collision">
      <origin rpy="0 0 0" xyz="0 0 -0.1275"/>
      <geometry>
        <cylinder length="0.10500000000000001" radius="0.04"/>
      </geometry>
    </collision>
  </link>
  <joint name="right_hip_yaw_joint" type="revolute">
    <origin rpy="0 0 0" xyz="-0.0422499999999986 0 -0.0520000000000019"/>
    <parent link="right_hip_roll_link"/>
    <child link="right_hip_yaw_link"/>
    <axis xyz="0 0 -1"/>
    <limit effort="120.0" lower="-0.698" upper="0.698" velocity="8"/>
    <dynamics damping="0.038" friction="0"/>
  </joint>
  <link name="right_knee_link">
    <inertial>
      <origin rpy="0 0 0" xyz="-0.000497587233719177 -0.000414757224949908 -0.16903904034355802"/>
      <mass value="3.5866525910256453"/>
      <inertia ixx="0.02164833481064742" ixy="-9.87527823922245E-06" ixz="-0.00064509471825313" iyy="0.02194396285606641" iyz="7.98431367388265E-06" izz="0.0034963553739372003"/>
    </inertial>
    <visual>
      <geometry>
        <mesh filename="C:/Projects/RevExBot/RevEx_Phase1_Hardware/mechanical/meshes/RIGHT_KNEE.STL" scale="1 1 1.5"/>
      </geometry>
      <material name="Grey"/>
    </visual>
    <collision name="right_knee_collision">
      <origin rpy="0 0 0" xyz="0 0 -0.195"/>
      <geometry>
        <cylinder length="0.27" radius="0.04"/>
      </geometry>
    </collision>
  </link>
  <joint name="right_knee_joint" type="revolute">
    <origin rpy="0 0 0" xyz="0 0 -0.293459999999997"/>
    <parent link="right_hip_yaw_link"/>
    <child link="right_knee_link"/>
    <axis xyz="0 -1 0"/>
    <limit effort="225.0" lower="-1.5" upper="0" velocity="8"/>
    <dynamics damping="0.0339552" friction="0"/>
  </joint>
  <link name="right_ankle_pitch_link">
    <inertial>
      <origin rpy="0 0 0" xyz="-0.0011793692600079 6.86716864900516E-08 -0.00617614582815973"/>
      <mass value="0.27308917159726"/>
      <inertia ixx="6.42659452121946E-05" ixy="-1.02281345760111E-10" ixz="-1.07558770084606E-06" iyy="8.0994434836127E-05" iyz="3.52701184357211E-10" izz="4.71926012791403E-05"/>
    </inertial>
    <visual>
      <geometry>
        <mesh filename="C:/Projects/RevExBot/RevEx_Phase1_Hardware/mechanical/meshes/RIGHT_ANKLE_A.STL"/>
      </geometry>
      <material name="Grey"/>
    </visual>
  </link>
  <joint name="right_ankle_pitch_joint" type="revolute">
    <origin rpy="0 0 0" xyz="0 0.0001 -0.4419935041305345"/>
    <parent link="right_knee_link"/>
    <child link="right_ankle_pitch_link"/>
    <axis xyz="0 -1 0"/>
    <limit effort="120.0" lower="-0.35" upper="0.35" velocity="8"/>
    <dynamics damping="0.0565056" friction="0"/>
  </joint>
  <link name="right_ankle_roll_link">
    <inertial>
      <origin rpy="0 0 0" xyz="0.037604624066622 -0.00113270119001645 -0.0120667519779089"/>
      <mass value="0.405640437504617"/>
      <inertia ixx="0.000186422034243703" ixy="-1.26826355108374E-05" ixz="-1.31347174356107E-05" iyy="0.000416154288220916" iyz="-5.51984757483379E-06" izz="0.00053831651520468"/>
    </inertial>
    <visual>
      <geometry>
        <mesh filename="C:/Projects/RevExBot/RevEx_Phase1_Hardware/mechanical/meshes/RIGHT_ANKLE_B.STL"/>
      </geometry>
      <material name="Grey"/>
    </visual>
  </link>
  <joint name="right_ankle_roll_joint" type="revolute">
    <origin rpy="0 0 0" xyz="-0.0015 0 -0.00999999200000001"/>
    <parent link="right_ankle_pitch_link"/>
    <child link="right_ankle_roll_link"/>
    <axis xyz="-1 0 0"/>
    <limit effort="75.0" lower="-0.1" upper="0.1" velocity="8"/>
    <dynamics damping="0.0565056" friction="0"/>
  </joint>
  <link name="right_toe_link">
    <inertial>
      <origin rpy="0 0 0" xyz="0.0320141754360937 -0.000816708013105544 -0.0141309094649689"/>
      <mass value="0.112221754054884"/>
      <inertia ixx="5.5358948695321e-05" ixy="0" ixz="0" iyy="3.65052769951383e-05" iyz="0" izz="8.54017357052965e-05"/>
    </inertial>
    <visual>
      <origin rpy="0 0 0" xyz="0 -0.008 0"/>
      <geometry>
        <mesh filename="C:/Projects/RevExBot/RevEx_Phase1_Hardware/mechanical/meshes/RIGHT_TOE.STL"/>
      </geometry>
      <material name="DarkGrey"/>
    </visual>
    <collision name="right_toe_collision">
      <origin rpy="0 0 0" xyz="0.025 0 0"/>
      <geometry>
        <box size="0.05 0.06 0.008"/>
      </geometry>
    </collision>
  </link>
  <joint name="right_toe_joint" type="revolute">
    <origin rpy="0 0 0" xyz="0.10247 0.0042796 -0.0067324"/>
    <parent link="right_ankle_roll_link"/>
    <child link="right_toe_link"/>
    <axis xyz="0.0074685 -0.99997 0"/>
    <limit effort="45.0" lower="-0.349" upper="1.047" velocity="8"/>
    <dynamics damping="0.001" friction="0.02"/>
  </joint>
  <link name="waist_yaw_link">
    <inertial>
      <origin rpy="0 0 0" xyz="-0.00699393636668848 -2.50812125574469E-05 0.20403987801712"/>
      <mass value="8.20850158063177"/>
      <inertia ixx="0.0498139710698645" ixy="-2.41115308804516E-05" ixz="0.00319230504367261" iyy="0.0397024417978058" iyz="-1.46092909936038E-05" izz="0.0321266580275838"/>
    </inertial>
    <visual>
      <geometry>
        <mesh filename="C:/Projects/RevExBot/RevEx_Phase1_Hardware/mechanical/meshes/WAIST_YAW.STL"/>
      </geometry>
      <material name="Grey"/>
    </visual>
    <collision name="waist_yaw_collision">
      <origin rpy="0 0 0" xyz="0 0 0.175"/>
      <geometry>
        <cylinder length="0.25" radius="0.06"/>
      </geometry>
    </collision>
  </link>
  <joint name="waist_yaw_joint" type="revolute">
    <origin rpy="0 0 0" xyz="-0.052 0 0.074755"/>
    <parent link="pelvis_link"/>
    <child link="waist_yaw_link"/>
    <axis xyz="0 0 1"/>
    <limit effort="150" lower="-1.047" upper="1.047" velocity="5"/>
    <dynamics damping="0.095625" friction="0"/>
  </joint>
  <link name="neck_yaw_link">
    <inertial>
      <origin rpy="0 0 0" xyz="0 0 0.01"/>
      <mass value="0.1"/>
      <inertia ixx="0.001" ixy="0" ixz="0" iyy="0.001" iyz="0" izz="0.001"/>
    </inertial>
    <visual>
      <origin rpy="0 0 0" xyz="0 0 0"/>
      <geometry>
        <mesh filename="C:/Projects/RevExBot/RevEx_Phase1_Hardware/mechanical/meshes/NECK_YAW.STL"/>
      </geometry>
      <material name="Grey"/>
    </visual>
  </link>
  <joint name="neck_yaw_joint" type="revolute">
    <origin rpy="0 0 0" xyz="-0.0165987745492247 0 0.37816702955645"/>
    <parent link="waist_yaw_link"/>
    <child link="neck_yaw_link"/>
    <axis xyz="0 0 1"/>
    <limit effort="20" lower="-1.571" upper="1.571" velocity="5"/>
    <dynamics damping="0.0565" friction="0"/>
  </joint>
  <link name="head_link">
    <inertial>
      <origin rpy="0 0 0" xyz="0 0 0.05"/>
      <mass value="0.5"/>
      <inertia ixx="0.01" ixy="0" ixz="0" iyy="0.01" iyz="0" izz="0.01"/>
    </inertial>
    <visual>
      <origin rpy="0 0 0" xyz="0 0 0"/>
      <geometry>
        <mesh filename="C:/Projects/RevExBot/RevEx_Phase1_Hardware/mechanical/meshes/head.stl"/>
      </geometry>
      <material name="LightGrey"/>
    </visual>
    <collision>
      <origin rpy="0 0 0" xyz="0 0 0.05"/>
      <geometry>
        <box size="0.2 0.16 0.12"/>
      </geometry>
    </collision>
  </link>
  <joint name="neck_pitch_joint" type="revolute">
    <origin rpy="0 0 0" xyz="0 0 0.0373499999999998"/>
    <parent link="neck_yaw_link"/>
    <child link="head_link"/>
    <axis xyz="0 1 0"/>
    <limit effort="20" lower="-0.5" upper="0.5" velocity="5"/>
    <dynamics damping="0.0565" friction="0"/>
  </joint>
  <link name="left_eye_camera_link"/>
  <link name="right_eye_camera_link"/>
  <joint name="head_to_left_eye" type="fixed">
    <parent link="head_link"/>
    <child link="left_eye_camera_link"/>
    <origin rpy="0 0 0" xyz="0.127 -0.031 0.115"/>
  </joint>
  <joint name="head_to_right_eye" type="fixed">
    <parent link="head_link"/>
    <child link="right_eye_camera_link"/>
    <origin rpy="0 0 0" xyz="0.127 0.031 0.115"/>
  </joint>
  <link name="left_ear_mic_link"/>
  <link name="right_ear_mic_link"/>
  <joint name="head_to_left_ear" type="fixed">
    <parent link="head_link"/>
    <child link="left_ear_mic_link"/>
    <origin rpy="0 0 0" xyz="0.126 0.029 0.115"/>
  </joint>
  <joint name="head_to_right_ear" type="fixed">
    <parent link="head_link"/>
    <child link="right_ear_mic_link"/>
    <origin rpy="0 0 0" xyz="0.126 -0.029 0.115"/>
  </joint>
  <link name="right_shoulder_pitch_link">
    <inertial>
      <origin rpy="0 0 0" xyz="0.000129810971033137 -0.0157921829692733 -1.88616919207796E-05"/>
      <mass value="0.599156105726411"/>
      <inertia ixx="0.000330318150839075" ixy="-2.56885268466272E-07" ixz="2.44063757734843E-09" iyy="0.000418513262392796" iyz="-3.98664414578714E-10" izz="0.000421384143645388"/>
    </inertial>
    <visual>
      <geometry>
        <mesh filename="C:/Projects/RevExBot/RevEx_Phase1_Hardware/mechanical/meshes/RIGHT_SHOULDER_PITCH.STL"/>
      </geometry>
      <material name="Grey"/>
    </visual>
  </link>
  <joint name="right_shoulder_pitch_joint" type="revolute">
    <origin rpy="0 -0.436332 0" xyz="-0.0262128253533167 -0.0964999999999998 0.261140483320038"/>
    <parent link="waist_yaw_link"/>
    <child link="right_shoulder_pitch_link"/>
    <axis xyz="0 -1 0"/>
    <limit effort="80" lower="-0.872" upper="3.141" velocity="6"/>
    <dynamics damping="0.11" friction="0"/>
  </joint>
  <link name="right_shoulder_roll_link">
    <inertial>
      <origin rpy="0 0 0" xyz="0.000114177624818339 -4.35142145794876E-05 -0.0373100689697469"/>
      <mass value="1.31322237625579"/>
      <inertia ixx="0.00163280464556345" ixy="4.4229503860379E-07" ixz="9.017972571202E-07" iyy="0.00149148477281863" iyz="3.09076703769813E-06" izz="0.000740785347833217"/>
    </inertial>
    <visual>
      <geometry>
        <mesh filename="C:/Projects/RevExBot/RevEx_Phase1_Hardware/mechanical/meshes/RIGHT_SHOULDER_ROLL.STL"/>
      </geometry>
      <material name="Grey"/>
    </visual>
    <collision name="right_shoulder_roll_collision">
      <origin rpy="0 0 0" xyz="0 -0.01 -0.065"/>
      <geometry>
        <cylinder length="0.09" radius="0.035"/>
      </geometry>
    </collision>
  </link>
  <joint name="right_shoulder_roll_joint" type="revolute">
    <origin rpy="0 0 0" xyz="0 -0.0653532232325457 -6.33413504113611E-05"/>
    <parent link="right_shoulder_pitch_link"/>
    <child link="right_shoulder_roll_link"/>
    <axis xyz="-1 0 0"/>
    <limit effort="80" lower="0" upper="1.571" velocity="6"/>
    <dynamics damping="0.0339552" friction="0"/>
  </joint>
  <link name="right_shoulder_yaw_link">
    <inertial>
      <origin rpy="0 0 0" xyz="-0.000325066122385375 0.000320503955106993 -0.0759404985004545"/>
      <mass value="0.712261755331765"/>
      <inertia ixx="0.000502664342430343" ixy="1.03874826912854E-07" ixz="3.84898679655994E-07" iyy="0.000516259495504905" iyz="-9.28406240892842E-07" izz="0.000310678003766854"/>
    </inertial>
    <visual>
      <geometry>
        <mesh filename="C:/Projects/RevExBot/RevEx_Phase1_Hardware/mechanical/meshes/RIGHT_SHOULDER_YAW.STL"/>
      </geometry>
      <material name="Grey"/>
    </visual>
  </link>
  <joint name="right_shoulder_yaw_joint" type="revolute">
    <origin rpy="0 0 0" xyz="0 0 -0.128998749978416"/>
    <parent link="right_shoulder_roll_link"/>
    <child link="right_shoulder_yaw_link"/>
    <axis xyz="0 0 -1"/>
    <limit effort="60" lower="-1.571" upper="1.571" velocity="6"/>
    <dynamics damping="0.038" friction="0"/>
  </joint>
  <link name="right_elbow_link">
    <inertial>
      <origin rpy="0 0 0" xyz="0.0523755985403483 -9.84304228299482E-05 -0.0444425911778195"/>
      <mass value="0.662314258886328"/>
      <inertia ixx="0.000331709977441628" ixy="1.14378770241915E-07" ixz="5.58706757420512E-05" iyy="0.000418432878642283" iyz="-9.7404268443382E-08" izz="0.00036781692231096"/>
    </inertial>
    <visual>
      <geometry>
        <mesh filename="C:/Projects/RevExBot/RevEx_Phase1_Hardware/mechanical/meshes/RIGHT_ELBOW.STL"/>
      </geometry>
      <material name="Grey"/>
    </visual>
    <collision name="right_elbow_collision">
      <origin rpy="0 0 0" xyz="0 -0.01 -0.035"/>
      <geometry>
        <cylinder length="0.08" radius="0.03"/>
      </geometry>
    </collision>
  </link>
  <joint name="right_elbow_joint" type="revolute">
    <origin rpy="0 0 0" xyz="0 0 -0.0966012999998862"/>
    <parent link="right_shoulder_yaw_link"/>
    <child link="right_elbow_link"/>
    <axis xyz="0 1 0"/>
    <limit effort="60" lower="-2.443" upper="0" velocity="6"/>
    <dynamics damping="0.0282528" friction="0"/>
  </joint>
  <link name="left_shoulder_pitch_link">
    <inertial>
      <origin rpy="0 0 0" xyz="0.000159889483543337 0.015791587441366 -3.48203187672258E-07"/>
      <mass value="0.599157136550892"/>
      <inertia ixx="0.000330315921264664" ixy="2.45535699672275E-07" ixz="-2.28363178468585E-09" iyy="0.000418517858443934" iyz="-1.01854853365967E-08" izz="0.000421379165524238"/>
    </inertial>
    <visual>
      <geometry>
        <mesh filename="C:/Projects/RevExBot/RevEx_Phase1_Hardware/mechanical/meshes/LEFT_SHOULDER_PITCH.STL"/>
      </geometry>
      <material name="Grey"/>
    </visual>
  </link>
  <joint name="left_shoulder_pitch_joint" type="revolute">
    <origin rpy="0 -0.436332 0" xyz="-0.0262128253533159 0.0965000000000001 0.261140483320038"/>
    <parent link="waist_yaw_link"/>
    <child link="left_shoulder_pitch_link"/>
    <axis xyz="0 1 0"/>
    <limit effort="80" lower="-3.141" upper="0.872" velocity="6"/>
    <dynamics damping="0.11" friction="0"/>
  </joint>
  <link name="left_shoulder_roll_link">
    <inertial>
      <origin rpy="0 0 0" xyz="0.00011401838763982 4.3288067202385E-05 -0.0373100597490998"/>
      <mass value="1.3132281302001"/>
      <inertia ixx="0.0016328136443199" ixy="-4.3632231123889E-07" ixz="9.06646221352916E-07" iyy="0.00149147489643918" iyz="-3.08459314459227E-06" izz="0.000740809790351389"/>
    </inertial>
    <visual>
      <geometry>
        <mesh filename="C:/Projects/RevExBot/RevEx_Phase1_Hardware/mechanical/meshes/LEFT_SHOULDER_ROLL.STL"/>
      </geometry>
      <material name="Grey"/>
    </visual>
    <collision name="left_shoulder_roll_collision">
      <origin rpy="0 0 0" xyz="0 0.01 -0.065"/>
      <geometry>
        <cylinder length="0.09" radius="0.035"/>
      </geometry>
    </collision>
  </link>
  <joint name="left_shoulder_roll_joint" type="revolute">
    <origin rpy="0 0 0" xyz="0.000100000000001779 0.0653532232325531 0"/>
    <parent link="left_shoulder_pitch_link"/>
    <child link="left_shoulder_roll_link"/>
    <axis xyz="-1 0 0"/>
    <limit effort="80" lower="-1.571" upper="0" velocity="6"/>
    <dynamics damping="0.0339552" friction="0"/>
  </joint>
  <link name="left_shoulder_yaw_link">
    <inertial>
      <origin rpy="0 0 0" xyz="-0.000330000636187981 0.000136036715123772 -0.0753619101773522"/>
      <mass value="0.712261755331765"/>
      <inertia ixx="0.000501395820111453" ixy="-1.0357243024011E-07" ixz="3.85724001728373E-07" iyy="0.000514632797400514" iyz="9.7896997590059E-07" izz="0.000310276967015705"/>
    </inertial>
    <visual>
      <geometry>
        <mesh filename="C:/Projects/RevExBot/RevEx_Phase1_Hardware/mechanical/meshes/LEFT_SHOULDER_YAW.STL"/>
      </geometry>
      <material name="Grey"/>
    </visual>
  </link>
  <joint name="left_shoulder_yaw_joint" type="revolute">
    <origin rpy="0 0 0" xyz="0 0 -0.128998749978194"/>
    <parent link="left_shoulder_roll_link"/>
    <child link="left_shoulder_yaw_link"/>
    <axis xyz="0 0 -1"/>
    <limit effort="60" lower="-1.571" upper="1.571" velocity="6"/>
    <dynamics damping="0.038" friction="0"/>
  </joint>
  <link name="left_elbow_link">
    <inertial>
      <origin rpy="0 0 0" xyz="0.0523756419047112 9.84723348319283E-05 -0.0444426425125844"/>
      <mass value="0.662317601299901"/>
      <inertia ixx="0.000331709518475136" ixy="-1.15265452395985E-07" ixz="5.58734246475865E-05" iyy="0.000418430298151774" iyz="9.67795385366457E-08" izz="0.000367817844214662"/>
    </inertial>
    <visual>
      <geometry>
        <mesh filename="C:/Projects/RevExBot/RevEx_Phase1_Hardware/mechanical/meshes/LEFT_ELBOW.STL"/>
      </geometry>
      <material name="Grey"/>
    </visual>
    <collision name="left_elbow_collision">
      <origin rpy="0 0 0" xyz="0 0.01 -0.035"/>
      <geometry>
        <cylinder length="0.08" radius="0.03"/>
      </geometry>
    </collision>
  </link>
  <joint name="left_elbow_joint" type="revolute">
    <origin rpy="0 0 0" xyz="0 0 -0.0963013000001065"/>
    <parent link="left_shoulder_yaw_link"/>
    <child link="left_elbow_link"/>
    <axis xyz="0 -1 0"/>
    <limit effort="60" lower="0" upper="2.443" velocity="6"/>
    <dynamics damping="0.0282528" friction="0"/>
  </joint>
  <link name="rh_forearm">
    <inertial>
      <origin rpy="0 0 0" xyz="0 0 0.09"/>
      <mass value="3.0"/>
      <inertia ixx="0.0138" ixy="0.0" ixz="0.0" iyy="0.0138" iyz="0.0" izz="0.00744"/>
    </inertial>
    <visual>
      <origin rpy="0 0 0" xyz="0.107504 0.162107 -0.113857"/>
      <geometry name="rh_forearm_visual">
        <mesh filename="C:/Projects/RevExBot/RevEx_Phase1_Hardware/mechanical/meshes/rh_forearm.stl"/>
      </geometry>
      <material name="light_grey">
        <color rgba="0.90000 0.90000 0.90000 1.0"/>
      </material>
    </visual>
    <collision>
      <origin rpy="0 0 0" xyz="0.107504 0.162107 -0.113857"/>
      <geometry name="rh_forearm_collision">
        <mesh filename="C:/Projects/RevExBot/RevEx_Phase1_Hardware/mechanical/meshes/rh_forearm.stl"/>
      </geometry>
    </collision>
    <collision>
      <origin rpy="0 0.78 0" xyz="0 -0.01 0.181"/>
      <geometry>
        <box size="0.07 0.07 0.07"/>
      </geometry>
    </collision>
  </link>
  <link name="rh_wrist">
    <inertial>
      <origin rpy="0 0 0" xyz="0 0 0.029"/>
      <mass value="0.1"/>
      <inertia ixx="0.000035" ixy="0.0" ixz="0.0" iyy="0.000064" iyz="0.0" izz="0.0000438"/>
    </inertial>
    <visual>
      <origin rpy="0 0 0" xyz="0 0 0"/>
      <geometry>
        <mesh filename="C:/Projects/RevExBot/RevEx_Phase1_Hardware/mechanical/meshes/rh_wrist_E3M5.stl"/>
      </geometry>
      <material name="LightGrey"/>
    </visual>
    <collision>
      <origin rpy="1.5708 1.5708 0" xyz="0 0 0"/>
      <geometry>
        <cylinder length="0.030" radius="0.0135"/>
      </geometry>
    </collision>
    <collision>
      <origin rpy="0 1.5708 0" xyz="-0.026 0 0.034"/>
      <geometry>
        <cylinder length="0.010" radius="0.011"/>
      </geometry>
    </collision>
    <collision>
      <origin rpy="0 1.5708 0" xyz="0.031 0 0.034"/>
      <geometry>
        <cylinder length="0.010" radius="0.011"/>
      </geometry>
    </collision>
    <collision>
      <origin rpy="0 0.7854 0" xyz="-0.021 0 0.011"/>
      <geometry>
        <box size="0.027 0.018 0.010"/>
      </geometry>
    </collision>
    <collision>
      <origin rpy="0 -0.7854 0" xyz="0.026 0 0.010"/>
      <geometry>
        <box size="0.027 0.018 0.010"/>
      </geometry>
    </collision>
  </link>
  <joint name="rh_WRJ2" type="revolute">
    <parent link="rh_forearm"/>
    <child link="rh_wrist"/>
    <origin rpy="3.14159 0.1396263 0" xyz="-0.013287 0 -0.248456"/>
    <axis xyz="0 1 0"/>
    <limit effort="10" lower="-0.5235987755982988" upper="0.17453292519943295" velocity="2.0"/>
    <dynamics damping="0.1"/>
  </joint>
  <link name="rh_palm">
    <inertial>
      <origin rpy="0 0 0" xyz="0 0 0.035"/>
      <mass value="0.3"/>
      <inertia ixx="0.0003581" ixy="0.0" ixz="0.0" iyy="0.0005287" iyz="0.0" izz="0.000191"/>
    </inertial>
    <visual>
      <origin rpy="0 0 0" xyz="0 0 0"/>
      <geometry>
        <mesh filename="C:/Projects/RevExBot/RevEx_Phase1_Hardware/mechanical/meshes/rh_palm_E3M5.stl"/>
      </geometry>
      <material name="Grey"/>
    </visual>
    <collision>
      <origin rpy="0 0 0" xyz="0.011 0.0085 0.038"/>
      <geometry>
        <box size="0.062 0.007 0.098"/>
      </geometry>
    </collision>
    <collision>
      <origin rpy="0 0 0" xyz="-0.002 -0.0035 0.038"/>
      <geometry>
        <box size="0.036 0.017 0.098"/>
      </geometry>
    </collision>
    <collision>
      <origin rpy="0 0 0" xyz="0.029 -0.0035 0.082"/>
      <geometry>
        <box size="0.026 0.017 0.010"/>
      </geometry>
    </collision>
    <collision>
      <origin rpy="0.2 0 0.25" xyz="0.0265 -0.001 0.070"/>
      <geometry>
        <box size="0.026 0.014 0.018"/>
      </geometry>
    </collision>
    <collision>
      <origin rpy="0 0 0" xyz="0.0315 -0.0085 0.001"/>
      <geometry>
        <box size="0.021 0.027 0.024"/>
      </geometry>
    </collision>
    <collision>
      <origin rpy="0 0 -0.48" xyz="0.0125 -0.015 0.009"/>
      <geometry>
        <box size="0.022 0.005 0.040"/>
      </geometry>
    </collision>
    <collision>
      <origin rpy="0 0 0" xyz="0.011 0 0.089"/>
      <geometry>
        <box size="0.018 0.024 0.004"/>
      </geometry>
    </collision>
    <collision>
      <origin rpy="0 0 0" xyz="-0.03 0 0.009"/>
      <geometry>
        <box size="0.020 0.024 0.040"/>
      </geometry>
    </collision>
  </link>
  <joint name="rh_WRJ1" type="revolute">
    <parent link="rh_wrist"/>
    <child link="rh_palm"/>
    <origin rpy="0 0 0" xyz="0 0 0.034"/>
    <axis xyz="1 0 0"/>
    <limit effort="30" lower="-0.6981317007977318" upper="0.4886921905584123" velocity="2.0"/>
    <dynamics damping="0.1"/>
  </joint>
  <link name="rh_manipulator"/>
  <joint name="rh_ee_fixed_joint" type="fixed">
    <parent link="rh_palm"/>
    <child link="rh_manipulator"/>
    <origin rpy="0.0 0.0 0.0" xyz="0.0 0.0 0.05"/>
  </joint>
  <link name="rh_imu"/>
  <joint name="rh_palm_to_imu" type="fixed">
    <parent link="rh_palm"/>
    <child link="rh_imu"/>
    <origin rpy="-1.5707963 3.141592 0.0" xyz="0.01785 0.00765 0.049125"/>
  </joint>
  <link name="rh_ffknuckle">
    <inertial>
      <origin rpy="0 0 0" xyz="0 0 0"/>
      <mass value="0.008"/>
      <inertia ixx="0.00000026" ixy="0.0" ixz="0.0" iyy="0.00000026" iyz="0.0" izz="0.00000032"/>
    </inertial>
    <visual>
      <origin rpy="0 0 0" xyz="0 0 0.0005"/>
      <geometry>
        <mesh filename="C:/Projects/RevExBot/RevEx_Phase1_Hardware/mechanical/meshes/rh_f_knuckle_E3M5.stl"/>
      </geometry>
      <material name="LightGrey"/>
    </visual>
    <collision>
      <origin rpy="0 1.5708 0" xyz="0 0 0"/>
      <geometry>
        <cylinder length="0.014" radius="0.007"/>
      </geometry>
    </collision>
  </link>
  <joint name="rh_FFJ4" type="revolute">
    <parent link="rh_palm"/>
    <child link="rh_ffknuckle"/>
    <origin rpy="0 0 0" xyz="0.033 0 0.095"/>
    <axis xyz="0 -1 0"/>
    <limit effort="2" lower="-0.3490658503988659" upper="0.3490658503988659" velocity="2.0"/>
    <dynamics damping="0.1"/>
  </joint>
  <link name="rh_ffproximal">
    <inertial>
      <mass value="0.030"/>
      <origin xyz="0 0 0.0225"/>
      <inertia ixx="0.0000098" ixy="0.0" ixz="0.0" iyy="0.00001" iyz="0.0" izz="0.0000018"/>
    </inertial>
    <visual>
      <origin rpy="0 0 0" xyz="0 0 0"/>
      <geometry>
        <mesh filename="C:/Projects/RevExBot/RevEx_Phase1_Hardware/mechanical/meshes/rh_f_proximal_E3M5.stl"/>
      </geometry>
      <material name="Grey"/>
    </visual>
    <collision>
      <origin rpy="0 0 0" xyz="0 0 0.025"/>
      <geometry>
        <cylinder length="0.040" radius="0.007"/>
      </geometry>
    </collision>
  </link>
  <joint name="rh_FFJ3" type="revolute">
    <parent link="rh_ffknuckle"/>
    <child link="rh_ffproximal"/>
    <origin rpy="0 0 0" xyz="0 0 0"/>
    <axis xyz="1 0 0"/>
    <limit effort="2" lower="-0.2617993877991494" upper="1.5707963267948966" velocity="2.0"/>
    <dynamics damping="0.1"/>
  </joint>
  <link name="rh_ffmiddle">
    <inertial>
      <origin rpy="0 0 0" xyz="0 0 0.0125"/>
      <mass value="0.017"/>
      <inertia ixx="0.0000026" ixy="0.0" ixz="0.0" iyy="0.0000027" iyz="0.0" izz="0.00000087"/>
    </inertial>
    <visual>
      <origin rpy="0 0 0" xyz="0 0 0"/>
      <geometry>
        <mesh filename="C:/Projects/RevExBot/RevEx_Phase1_Hardware/mechanical/meshes/rh_f_middle_E3M5.stl"/>
      </geometry>
      <material name="Grey"/>
    </visual>
    <collision>
      <origin rpy="0 0 0" xyz="0 0 0.0125"/>
      <geometry>
        <cylinder length="0.025" radius="0.007"/>
      </geometry>
    </collision>
    <collision>
      <origin rpy="0 0 0" xyz="0 0 0.0"/>
      <geometry>
        <sphere radius="0.007"/>
      </geometry>
    </collision>
    <collision>
      <origin rpy="0 0 0" xyz="0 0 0.025"/>
      <geometry>
        <sphere radius="0.007"/>
      </geometry>
    </collision>
  </link>
  <joint name="rh_FFJ2" type="revolute">
    <parent link="rh_ffproximal"/>
    <child link="rh_ffmiddle"/>
    <origin rpy="0 0 0" xyz="0 0 0.045"/>
    <axis xyz="1 0 0"/>
    <limit effort="2" lower="0" upper="1.5707963267948966" velocity="2.0"/>
    <dynamics damping="0.1"/>
  </joint>
  <link name="rh_ffdistal">
    <inertial>
      <mass value="0.012"/>
      <origin xyz="0 0 0.012"/>
      <inertia ixx="0.00000094" ixy="0.0" ixz="0.0" iyy="0.0000011" iyz="0.0" izz="0.00000053"/>
    </inertial>
    <visual>
      <origin rpy="0 0 0" xyz="0 0 0"/>
      <geometry>
        <mesh filename="C:/Projects/RevExBot/RevEx_Phase1_Hardware/mechanical/meshes/rh_f_distal_pst.stl"/>
      </geometry>
    </visual>
    <collision>
      <origin rpy="0 0 0" xyz="0 0 0"/>
      <geometry>
        <mesh filename="C:/Projects/RevExBot/RevEx_Phase1_Hardware/mechanical/meshes/rh_f_distal_pst.stl"/>
      </geometry>
    </collision>
  </link>
  <joint name="rh_FFJ1" type="revolute">
    <parent link="rh_ffmiddle"/>
    <child link="rh_ffdistal"/>
    <origin rpy="0 0 0" xyz="0 0 0.025"/>
    <axis xyz="1 0 0"/>
    <limit effort="2" lower="0" upper="1.5707963267948966" velocity="2.0"/>
    <dynamics damping="0.1"/>
  </joint>
  <link name="rh_fftip">
    <inertial>
      <mass value="0.001"/>
      <inertia ixx="0.00001" ixy="0.0" ixz="0.0" iyy="0.00001" iyz="0.0" izz="0.00001"/>
    </inertial>
  </link>
  <joint name="rh_FFtip" type="fixed">
    <parent link="rh_ffdistal"/>
    <child link="rh_fftip"/>
    <origin rpy="0 0 0" xyz="0 0 0.026"/>
  </joint>
  <link name="rh_mfknuckle">
    <inertial>
      <origin rpy="0 0 0" xyz="0 0 0"/>
      <mass value="0.008"/>
      <inertia ixx="0.00000026" ixy="0.0" ixz="0.0" iyy="0.00000026" iyz="0.0" izz="0.00000032"/>
    </inertial>
    <visual>
      <origin rpy="0 0 0" xyz="0 0 0.0005"/>
      <geometry>
        <mesh filename="C:/Projects/RevExBot/RevEx_Phase1_Hardware/mechanical/meshes/rh_f_knuckle_E3M5.stl"/>
      </geometry>
      <material name="LightGrey"/>
    </visual>
    <collision>
      <origin rpy="0 1.5708 0" xyz="0 0 0"/>
      <geometry>
        <cylinder length="0.014" radius="0.007"/>
      </geometry>
    </collision>
  </link>
  <joint name="rh_MFJ4" type="revolute">
    <parent link="rh_palm"/>
    <child link="rh_mfknuckle"/>
    <origin rpy="0 0 0" xyz="0.011 0 0.099"/>
    <axis xyz="0 -1 0"/>
    <limit effort="2" lower="-0.3490658503988659" upper="0.3490658503988659" velocity="2.0"/>
    <dynamics damping="0.1"/>
  </joint>
  <link name="rh_mfproximal">
    <inertial>
      <mass value="0.030"/>
      <origin xyz="0 0 0.0225"/>
      <inertia ixx="0.0000098" ixy="0.0" ixz="0.0" iyy="0.00001" iyz="0.0" izz="0.0000018"/>
    </inertial>
    <visual>
      <origin rpy="0 0 0" xyz="0 0 0"/>
      <geometry>
        <mesh filename="C:/Projects/RevExBot/RevEx_Phase1_Hardware/mechanical/meshes/rh_f_proximal_E3M5.stl"/>
      </geometry>
      <material name="Grey"/>
    </visual>
    <collision>
      <origin rpy="0 0 0" xyz="0 0 0.025"/>
      <geometry>
        <cylinder length="0.040" radius="0.007"/>
      </geometry>
    </collision>
  </link>
  <joint name="rh_MFJ3" type="revolute">
    <parent link="rh_mfknuckle"/>
    <child link="rh_mfproximal"/>
    <origin rpy="0 0 0" xyz="0 0 0"/>
    <axis xyz="1 0 0"/>
    <limit effort="2" lower="-0.2617993877991494" upper="1.5707963267948966" velocity="2.0"/>
    <dynamics damping="0.1"/>
  </joint>
  <link name="rh_mfmiddle">
    <inertial>
      <origin rpy="0 0 0" xyz="0 0 0.0125"/>
      <mass value="0.017"/>
      <inertia ixx="0.0000026" ixy="0.0" ixz="0.0" iyy="0.0000027" iyz="0.0" izz="0.00000087"/>
    </inertial>
    <visual>
      <origin rpy="0 0 0" xyz="0 0 0"/>
      <geometry>
        <mesh filename="C:/Projects/RevExBot/RevEx_Phase1_Hardware/mechanical/meshes/rh_f_middle_E3M5.stl"/>
      </geometry>
      <material name="Grey"/>
    </visual>
    <collision>
      <origin rpy="0 0 0" xyz="0 0 0.0125"/>
      <geometry>
        <cylinder length="0.025" radius="0.007"/>
      </geometry>
    </collision>
    <collision>
      <origin rpy="0 0 0" xyz="0 0 0.0"/>
      <geometry>
        <sphere radius="0.007"/>
      </geometry>
    </collision>
    <collision>
      <origin rpy="0 0 0" xyz="0 0 0.025"/>
      <geometry>
        <sphere radius="0.007"/>
      </geometry>
    </collision>
  </link>
  <joint name="rh_MFJ2" type="revolute">
    <parent link="rh_mfproximal"/>
    <child link="rh_mfmiddle"/>
    <origin rpy="0 0 0" xyz="0 0 0.045"/>
    <axis xyz="1 0 0"/>
    <limit effort="2" lower="0" upper="1.5707963267948966" velocity="2.0"/>
    <dynamics damping="0.1"/>
  </joint>
  <link name="rh_mfdistal">
    <inertial>
      <mass value="0.012"/>
      <origin xyz="0 0 0.012"/>
      <inertia ixx="0.00000094" ixy="0.0" ixz="0.0" iyy="0.0000011" iyz="0.0" izz="0.00000053"/>
    </inertial>
    <visual>
      <origin rpy="0 0 0" xyz="0 0 0"/>
      <geometry>
        <mesh filename="C:/Projects/RevExBot/RevEx_Phase1_Hardware/mechanical/meshes/rh_f_distal_pst.stl"/>
      </geometry>
    </visual>
    <collision>
      <origin rpy="0 0 0" xyz="0 0 0"/>
      <geometry>
        <mesh filename="C:/Projects/RevExBot/RevEx_Phase1_Hardware/mechanical/meshes/rh_f_distal_pst.stl"/>
      </geometry>
    </collision>
  </link>
  <joint name="rh_MFJ1" type="revolute">
    <parent link="rh_mfmiddle"/>
    <child link="rh_mfdistal"/>
    <origin rpy="0 0 0" xyz="0 0 0.025"/>
    <axis xyz="1 0 0"/>
    <limit effort="2" lower="0" upper="1.5707963267948966" velocity="2.0"/>
    <dynamics damping="0.1"/>
  </joint>
  <link name="rh_mftip">
    <inertial>
      <mass value="0.001"/>
      <inertia ixx="0.00001" ixy="0.0" ixz="0.0" iyy="0.00001" iyz="0.0" izz="0.00001"/>
    </inertial>
  </link>
  <joint name="rh_MFtip" type="fixed">
    <parent link="rh_mfdistal"/>
    <child link="rh_mftip"/>
    <origin rpy="0 0 0" xyz="0 0 0.026"/>
  </joint>
  <link name="rh_rfknuckle">
    <inertial>
      <origin rpy="0 0 0" xyz="0 0 0"/>
      <mass value="0.008"/>
      <inertia ixx="0.00000026" ixy="0.0" ixz="0.0" iyy="0.00000026" iyz="0.0" izz="0.00000032"/>
    </inertial>
    <visual>
      <origin rpy="0 0 0" xyz="0 0 0.0005"/>
      <geometry>
        <mesh filename="C:/Projects/RevExBot/RevEx_Phase1_Hardware/mechanical/meshes/rh_f_knuckle_E3M5.stl"/>
      </geometry>
      <material name="LightGrey"/>
    </visual>
    <collision>
      <origin rpy="0 1.5708 0" xyz="0 0 0"/>
      <geometry>
        <cylinder length="0.014" radius="0.007"/>
      </geometry>
    </collision>
  </link>
  <joint name="rh_RFJ4" type="revolute">
    <parent link="rh_palm"/>
    <child link="rh_rfknuckle"/>
    <origin rpy="0 0 0" xyz="-0.011 0 0.095"/>
    <axis xyz="0 1 0"/>
    <limit effort="2" lower="-0.3490658503988659" upper="0.3490658503988659" velocity="2.0"/>
    <dynamics damping="0.1"/>
  </joint>
  <link name="rh_rfproximal">
    <inertial>
      <mass value="0.030"/>
      <origin xyz="0 0 0.0225"/>
      <inertia ixx="0.0000098" ixy="0.0" ixz="0.0" iyy="0.00001" iyz="0.0" izz="0.0000018"/>
    </inertial>
    <visual>
      <origin rpy="0 0 0" xyz="0 0 0"/>
      <geometry>
        <mesh filename="C:/Projects/RevExBot/RevEx_Phase1_Hardware/mechanical/meshes/rh_f_proximal_E3M5.stl"/>
      </geometry>
      <material name="Grey"/>
    </visual>
    <collision>
      <origin rpy="0 0 0" xyz="0 0 0.025"/>
      <geometry>
        <cylinder length="0.040" radius="0.007"/>
      </geometry>
    </collision>
  </link>
  <joint name="rh_RFJ3" type="revolute">
    <parent link="rh_rfknuckle"/>
    <child link="rh_rfproximal"/>
    <origin rpy="0 0 0" xyz="0 0 0"/>
    <axis xyz="1 0 0"/>
    <limit effort="2" lower="-0.2617993877991494" upper="1.5707963267948966" velocity="2.0"/>
    <dynamics damping="0.1"/>
  </joint>
  <link name="rh_rfmiddle">
    <inertial>
      <origin rpy="0 0 0" xyz="0 0 0.0125"/>
      <mass value="0.017"/>
      <inertia ixx="0.0000026" ixy="0.0" ixz="0.0" iyy="0.0000027" iyz="0.0" izz="0.00000087"/>
    </inertial>
    <visual>
      <origin rpy="0 0 0" xyz="0 0 0"/>
      <geometry>
        <mesh filename="C:/Projects/RevExBot/RevEx_Phase1_Hardware/mechanical/meshes/rh_f_middle_E3M5.stl"/>
      </geometry>
      <material name="Grey"/>
    </visual>
    <collision>
      <origin rpy="0 0 0" xyz="0 0 0.0125"/>
      <geometry>
        <cylinder length="0.025" radius="0.007"/>
      </geometry>
    </collision>
    <collision>
      <origin rpy="0 0 0" xyz="0 0 0.0"/>
      <geometry>
        <sphere radius="0.007"/>
      </geometry>
    </collision>
    <collision>
      <origin rpy="0 0 0" xyz="0 0 0.025"/>
      <geometry>
        <sphere radius="0.007"/>
      </geometry>
    </collision>
  </link>
  <joint name="rh_RFJ2" type="revolute">
    <parent link="rh_rfproximal"/>
    <child link="rh_rfmiddle"/>
    <origin rpy="0 0 0" xyz="0 0 0.045"/>
    <axis xyz="1 0 0"/>
    <limit effort="2" lower="0" upper="1.5707963267948966" velocity="2.0"/>
    <dynamics damping="0.1"/>
  </joint>
  <link name="rh_rfdistal">
    <inertial>
      <mass value="0.012"/>
      <origin xyz="0 0 0.012"/>
      <inertia ixx="0.00000094" ixy="0.0" ixz="0.0" iyy="0.0000011" iyz="0.0" izz="0.00000053"/>
    </inertial>
    <visual>
      <origin rpy="0 0 0" xyz="0 0 0"/>
      <geometry>
        <mesh filename="C:/Projects/RevExBot/RevEx_Phase1_Hardware/mechanical/meshes/rh_f_distal_pst.stl"/>
      </geometry>
    </visual>
    <collision>
      <origin rpy="0 0 0" xyz="0 0 0"/>
      <geometry>
        <mesh filename="C:/Projects/RevExBot/RevEx_Phase1_Hardware/mechanical/meshes/rh_f_distal_pst.stl"/>
      </geometry>
    </collision>
  </link>
  <joint name="rh_RFJ1" type="revolute">
    <parent link="rh_rfmiddle"/>
    <child link="rh_rfdistal"/>
    <origin rpy="0 0 0" xyz="0 0 0.025"/>
    <axis xyz="1 0 0"/>
    <limit effort="2" lower="0" upper="1.5707963267948966" velocity="2.0"/>
    <dynamics damping="0.1"/>
  </joint>
  <link name="rh_rftip">
    <inertial>
      <mass value="0.001"/>
      <inertia ixx="0.00001" ixy="0.0" ixz="0.0" iyy="0.00001" iyz="0.0" izz="0.00001"/>
    </inertial>
  </link>
  <joint name="rh_RFtip" type="fixed">
    <parent link="rh_rfdistal"/>
    <child link="rh_rftip"/>
    <origin rpy="0 0 0" xyz="0 0 0.026"/>
  </joint>
  <link name="rh_lfmetacarpal">
    <inertial>
      <origin rpy="0 0.9599 0" xyz="0.031748676 0 0.02235294"/>
      <mass value="0.030"/>
      <inertia ixx="0.0000145" ixy="0.0" ixz="0.0" iyy="0.00001638" iyz="0.0" izz="0.000004272"/>
    </inertial>
    <visual>
      <origin rpy="0 0.9599 0" xyz="0 0 0"/>
      <geometry>
        <mesh filename="C:/Projects/RevExBot/RevEx_Phase1_Hardware/mechanical/meshes/rh_lf_metacarpal_E3M5.stl"/>
      </geometry>
      <material name="Grey"/>
    </visual>
    <collision>
      <origin rpy="0 0.9599 0" xyz="0.026986375 0 0.019"/>
      <geometry>
        <box size="0.018 0.024 0.040"/>
      </geometry>
    </collision>
  </link>
  <joint name="rh_LFJ5" type="revolute">
    <parent link="rh_palm"/>
    <child link="rh_lfmetacarpal"/>
    <origin rpy="0 -0.9599 0" xyz="-0.033 0 0.02071"/>
    <axis xyz="1 0 0"/>
    <limit effort="2" lower="0" upper="0.7853981633974483" velocity="2.0"/>
    <dynamics damping="0.1"/>
  </joint>
  <link name="rh_lfknuckle">
    <inertial>
      <origin rpy="0 0 0" xyz="0 0 0"/>
      <mass value="0.008"/>
      <inertia ixx="0.00000026" ixy="0.0" ixz="0.0" iyy="0.00000026" iyz="0.0" izz="0.00000032"/>
    </inertial>
    <visual>
      <origin rpy="0 0 0" xyz="0 0 0.0005"/>
      <geometry>
        <mesh filename="C:/Projects/RevExBot/RevEx_Phase1_Hardware/mechanical/meshes/rh_f_knuckle_E3M5.stl"/>
      </geometry>
      <material name="LightGrey"/>
    </visual>
    <collision>
      <origin rpy="0 1.5708 0" xyz="0 0 0"/>
      <geometry>
        <cylinder length="0.014" radius="0.007"/>
      </geometry>
    </collision>
  </link>
  <joint name="rh_LFJ4" type="revolute">
    <parent link="rh_lfmetacarpal"/>
    <child link="rh_lfknuckle"/>
    <origin rpy="0 0.9599 0" xyz="0.05397275 0 0.03779463"/>
    <axis xyz="0 1 0"/>
    <limit effort="2" lower="-0.3490658503988659" upper="0.3490658503988659" velocity="2.0"/>
    <dynamics damping="0.1"/>
  </joint>
  <link name="rh_lfknuckle">
    <inertial>
      <origin rpy="0 0 0" xyz="0 0 0"/>
      <mass value="0.008"/>
      <inertia ixx="0.00000026" ixy="0.0" ixz="0.0" iyy="0.00000026" iyz="0.0" izz="0.00000032"/>
    </inertial>
    <visual>
      <origin rpy="0 0 0" xyz="0 0 0.0005"/>
      <geometry>
        <mesh filename="C:/Projects/RevExBot/RevEx_Phase1_Hardware/mechanical/meshes/rh_f_knuckle_E3M5.stl"/>
      </geometry>
      <material name="LightGrey"/>
    </visual>
    <collision>
      <origin rpy="0 1.5708 0" xyz="0 0 0"/>
      <geometry>
        <cylinder length="0.014" radius="0.007"/>
      </geometry>
    </collision>
  </link>
  <link name="rh_lfproximal">
    <inertial>
      <mass value="0.030"/>
      <origin xyz="0 0 0.0225"/>
      <inertia ixx="0.0000098" ixy="0.0" ixz="0.0" iyy="0.00001" iyz="0.0" izz="0.0000018"/>
    </inertial>
    <visual>
      <origin rpy="0 0 0" xyz="0 0 0"/>
      <geometry>
        <mesh filename="C:/Projects/RevExBot/RevEx_Phase1_Hardware/mechanical/meshes/rh_f_proximal_E3M5.stl"/>
      </geometry>
      <material name="Grey"/>
    </visual>
    <collision>
      <origin rpy="0 0 0" xyz="0 0 0.025"/>
      <geometry>
        <cylinder length="0.040" radius="0.007"/>
      </geometry>
    </collision>
  </link>
  <joint name="rh_LFJ3" type="revolute">
    <parent link="rh_lfknuckle"/>
    <child link="rh_lfproximal"/>
    <origin rpy="0 0 0" xyz="0 0 0"/>
    <axis xyz="1 0 0"/>
    <limit effort="2" lower="-0.2617993877991494" upper="1.5707963267948966" velocity="2.0"/>
    <dynamics damping="0.1"/>
  </joint>
  <link name="rh_lfmiddle">
    <inertial>
      <origin rpy="0 0 0" xyz="0 0 0.0125"/>
      <mass value="0.017"/>
      <inertia ixx="0.0000026" ixy="0.0" ixz="0.0" iyy="0.0000027" iyz="0.0" izz="0.00000087"/>
    </inertial>
    <visual>
      <origin rpy="0 0 0" xyz="0 0 0"/>
      <geometry>
        <mesh filename="C:/Projects/RevExBot/RevEx_Phase1_Hardware/mechanical/meshes/rh_f_middle_E3M5.stl"/>
      </geometry>
      <material name="Grey"/>
    </visual>
    <collision>
      <origin rpy="0 0 0" xyz="0 0 0.0125"/>
      <geometry>
        <cylinder length="0.025" radius="0.007"/>
      </geometry>
    </collision>
    <collision>
      <origin rpy="0 0 0" xyz="0 0 0.0"/>
      <geometry>
        <sphere radius="0.007"/>
      </geometry>
    </collision>
    <collision>
      <origin rpy="0 0 0" xyz="0 0 0.025"/>
      <geometry>
        <sphere radius="0.007"/>
      </geometry>
    </collision>
  </link>
  <joint name="rh_LFJ2" type="revolute">
    <parent link="rh_lfproximal"/>
    <child link="rh_lfmiddle"/>
    <origin rpy="0 0 0" xyz="0 0 0.045"/>
    <axis xyz="1 0 0"/>
    <limit effort="2" lower="0" upper="1.5707963267948966" velocity="2.0"/>
    <dynamics damping="0.1"/>
  </joint>
  <link name="rh_lfdistal">
    <inertial>
      <mass value="0.012"/>
      <origin xyz="0 0 0.012"/>
      <inertia ixx="0.00000094" ixy="0.0" ixz="0.0" iyy="0.0000011" iyz="0.0" izz="0.00000053"/>
    </inertial>
    <visual>
      <origin rpy="0 0 0" xyz="0 0 0"/>
      <geometry>
        <mesh filename="C:/Projects/RevExBot/RevEx_Phase1_Hardware/mechanical/meshes/rh_f_distal_pst.stl"/>
      </geometry>
    </visual>
    <collision>
      <origin rpy="0 0 0" xyz="0 0 0"/>
      <geometry>
        <mesh filename="C:/Projects/RevExBot/RevEx_Phase1_Hardware/mechanical/meshes/rh_f_distal_pst.stl"/>
      </geometry>
    </collision>
  </link>
  <joint name="rh_LFJ1" type="revolute">
    <parent link="rh_lfmiddle"/>
    <child link="rh_lfdistal"/>
    <origin rpy="0 0 0" xyz="0 0 0.025"/>
    <axis xyz="1 0 0"/>
    <limit effort="2" lower="0" upper="1.5707963267948966" velocity="2.0"/>
    <dynamics damping="0.1"/>
  </joint>
  <link name="rh_lftip">
    <inertial>
      <mass value="0.001"/>
      <inertia ixx="0.00001" ixy="0.0" ixz="0.0" iyy="0.00001" iyz="0.0" izz="0.00001"/>
    </inertial>
  </link>
  <joint name="rh_LFtip" type="fixed">
    <parent link="rh_lfdistal"/>
    <child link="rh_lftip"/>
    <origin rpy="0 0 0" xyz="0 0 0.026"/>
  </joint>
  <link name="rh_thbase">
    <inertial>
      <mass value="0.010"/>
      <origin rpy="0 0 0" xyz="0 0 0"/>
      <inertia ixx="0.00000016" ixy="0.0" ixz="0.0" iyy="0.00000016" iyz="0.0" izz="0.00000016"/>
    </inertial>
    <visual>
      <origin rpy="0 0 0" xyz="0 0 0"/>
      <geometry>
        <box size="0.001 0.001 0.001"/>
      </geometry>
      <material name="shadow_thbase_material">
        <color rgba="0.5 0.5 0.5 1.0"/>
      </material>
    </visual>
    <collision>
      <origin rpy="0 0 0" xyz="0 0 0"/>
      <geometry>
        <sphere radius="0.011"/>
      </geometry>
    </collision>
  </link>
  <joint name="rh_THJ5" type="revolute">
    <parent link="rh_palm"/>
    <child link="rh_thbase"/>
    <origin rpy="-0.7853981633974483 0 -1.5707963267948966" xyz="0.034 -0.00858 0.029"/>
    <axis xyz="0 0 -1"/>
    <limit effort="5.0" lower="-1.0471975511965976" upper="1.0471975511965976" velocity="4.0"/>
    <dynamics damping="0.2"/>
  </joint>
  <link name="rh_thproximal">
    <inertial>
      <mass value="0.040"/>
      <origin rpy="0 0 0" xyz="0 0 0.019"/>
      <inertia ixx="0.0000136" ixy="0.0" ixz="0.0" iyy="0.0000136" iyz="0.0" izz="0.00000313"/>
    </inertial>
    <visual>
      <origin rpy="0 0 1.5707963267948966" xyz="0 0 0"/>
      <geometry>
        <mesh filename="C:/Projects/RevExBot/RevEx_Phase1_Hardware/mechanical/meshes/rh_th_proximal_E3M5.stl"/>
      </geometry>
      <material name="shadow_thproximal_material">
        <color rgba="0.2 0.2 0.2 1.0"/>
      </material>
    </visual>
    <collision>
      <origin rpy="0 0 0" xyz="0 0 0.020"/>
      <geometry>
        <cylinder length="0.018" radius="0.012"/>
      </geometry>
    </collision>
  </link>
  <joint name="rh_THJ4" type="revolute">
    <parent link="rh_thbase"/>
    <child link="rh_thproximal"/>
    <origin rpy="0 0 0" xyz="0 0 0"/>
    <axis xyz="0 1 0"/>
    <limit effort="3" lower="0.0" upper="1.2217304763960306" velocity="4.0"/>
    <dynamics damping="0.2"/>
  </joint>
  <link name="rh_thhub">
    <inertial>
      <mass value="0.005"/>
      <origin rpy="0 0 0" xyz="0 0 0"/>
      <inertia ixx="0.000001" ixy="0.0" ixz="0.0" iyy="0.000001" iyz="0.0" izz="0.0000003"/>
    </inertial>
    <visual>
      <origin rpy="0 0 0" xyz="0 0 0"/>
      <geometry>
        <box size="0.001 0.001 0.001"/>
      </geometry>
      <material name="shadow_thhub_material">
        <color rgba="0.7 0.7 0.7 1.0"/>
      </material>
    </visual>
    <collision>
      <origin rpy="0 0 0" xyz="0 0 0"/>
      <geometry>
        <sphere radius="0.010"/>
      </geometry>
    </collision>
  </link>
  <joint name="rh_THJ3" type="revolute">
    <parent link="rh_thproximal"/>
    <child link="rh_thhub"/>
    <origin rpy="0 0 0" xyz="0 0 0.038"/>
    <axis xyz="0 1 0"/>
    <limit effort="2.0" lower="-0.20943951023931953" upper="0.20943951023931953" velocity="4.0"/>
    <dynamics damping="0.2"/>
  </joint>
  <link name="rh_thmiddle">
    <inertial>
      <mass value="0.020"/>
      <origin rpy="0 0 0" xyz="0 0 0.016"/>
      <inertia ixx="0.0000051" ixy="0.0" ixz="0.0" iyy="0.0000051" iyz="0.0" izz="0.00000121"/>
    </inertial>
    <visual>
      <origin rpy="0 0 1.5707963267948966" xyz="0 0 0"/>
      <geometry>
        <mesh filename="C:/Projects/RevExBot/RevEx_Phase1_Hardware/mechanical/meshes/rh_th_middle_E3M5.stl"/>
      </geometry>
      <material name="shadow_thmiddle_material">
        <color rgba="0.2 0.2 0.2 1.0"/>
      </material>
    </visual>
    <collision>
      <origin rpy="0 0 0" xyz="0 0 0.012"/>
      <geometry>
        <cylinder length="0.018" radius="0.011"/>
      </geometry>
    </collision>
    <collision>
      <origin rpy="0 0 0" xyz="0 0 0.019"/>
      <geometry>
        <sphere radius="0.011"/>
      </geometry>
    </collision>
    <collision>
      <origin rpy="0 1.5708 0" xyz="0 0 0.032"/>
      <geometry>
        <cylinder length="0.014" radius="0.010"/>
      </geometry>
    </collision>
  </link>
  <joint name="rh_THJ2" type="revolute">
    <parent link="rh_thhub"/>
    <child link="rh_thmiddle"/>
    <origin rpy="0 0 0" xyz="0 0 0"/>
    <axis xyz="1 0 0"/>
    <limit effort="2.0" lower="-0.6981317007977318" upper="0.6981317007977318" velocity="2.0"/>
    <dynamics damping="0.1"/>
  </joint>
  <link name="rh_thdistal">
    <inertial>
      <mass value="0.016"/>
      <origin rpy="0 0 0" xyz="0 0 0.01375"/>
      <inertia ixx="0.0000021" ixy="0.0" ixz="0.0" iyy="0.0000022" iyz="0.0" izz="0.000001"/>
    </inertial>
    <visual>
      <origin rpy="0 0 0" xyz="0 0 0"/>
      <geometry>
        <mesh filename="C:/Projects/RevExBot/RevEx_Phase1_Hardware/mechanical/meshes/rh_th_distal_pst.stl"/>
      </geometry>
      <material name="shadow_thmiddle_material">
        <color rgba="0.2 0.2 0.2 1.0"/>
      </material>
    </visual>
    <collision>
      <origin rpy="0 0 0" xyz="0 0 0"/>
      <geometry>
        <mesh filename="C:/Projects/RevExBot/RevEx_Phase1_Hardware/mechanical/meshes/rh_th_distal_pst.stl"/>
      </geometry>
    </collision>
  </link>
  <joint name="rh_THJ1" type="revolute">
    <parent link="rh_thmiddle"/>
    <child link="rh_thdistal"/>
    <origin rpy="0 0 0" xyz="0 0 0.032"/>
    <axis xyz="1 0 0"/>
    <limit effort="1.0" lower="-0.2617993877991494" upper="1.5707963267948966" velocity="4.0"/>
    <dynamics damping="0.2"/>
  </joint>
  <link name="rh_thtip">
    <inertial>
      <mass value="0.001"/>
      <inertia ixx="0.00001" ixy="0.0" ixz="0.0" iyy="0.00001" iyz="0.0" izz="0.00001"/>
    </inertial>
  </link>
  <joint name="rh_thtip" type="fixed">
    <parent link="rh_thdistal"/>
    <child link="rh_thtip"/>
    <origin rpy="0 0 0" xyz="0 0 0.0275"/>
  </joint>
  <joint name="right_elbow_to_forearm_glue" type="fixed">
    <parent link="right_elbow_link"/>
    <child link="rh_forearm"/>
    <origin rpy="0 -0.1396263 0" xyz="0 0 0"/>
  </joint>
  <link name="lh_forearm">
    <inertial>
      <origin rpy="0 0 0" xyz="0 0 0.09"/>
      <mass value="3.0"/>
      <inertia ixx="0.0138" ixy="0.0" ixz="0.0" iyy="0.0138" iyz="0.0" izz="0.00744"/>
    </inertial>
    <visual>
      <origin rpy="0 0 0" xyz="0.107504 -0.162107 -0.113857"/>
      <geometry name="lh_forearm_visual">
        <mesh filename="C:/Projects/RevExBot/RevEx_Phase1_Hardware/mechanical/meshes/lh_forearm.stl"/>
      </geometry>
      <material name="light_grey">
        <color rgba="0.90000 0.90000 0.90000 1.0"/>
      </material>
    </visual>
    <collision>
      <origin rpy="0 0 0" xyz="0.107504 -0.162107 -0.113857"/>
      <geometry name="lh_forearm_collision">
        <mesh filename="C:/Projects/RevExBot/RevEx_Phase1_Hardware/mechanical/meshes/lh_forearm.stl"/>
      </geometry>
    </collision>
    <collision>
      <origin rpy="0 0.78 0" xyz="0 -0.01 0.181"/>
      <geometry>
        <box size="0.07 0.07 0.07"/>
      </geometry>
    </collision>
  </link>
  <link name="lh_wrist">
    <inertial>
      <origin rpy="0 0 0" xyz="0 0 0.029"/>
      <mass value="0.1"/>
      <inertia ixx="0.000035" ixy="0.0" ixz="0.0" iyy="0.000064" iyz="0.0" izz="0.0000438"/>
    </inertial>
    <visual>
      <origin rpy="0 0 0" xyz="0 0 0"/>
      <geometry>
        <mesh filename="C:/Projects/RevExBot/RevEx_Phase1_Hardware/mechanical/meshes/lh_wrist_E3M5.stl"/>
      </geometry>
      <material name="LightGrey"/>
    </visual>
    <collision>
      <origin rpy="-1.5708 1.5708 0" xyz="0 0 0"/>
      <geometry>
        <cylinder length="0.030" radius="0.0135"/>
      </geometry>
    </collision>
    <collision>
      <origin rpy="0 1.5708 0" xyz="0.026 0 0.034"/>
      <geometry>
        <cylinder length="0.010" radius="0.011"/>
      </geometry>
    </collision>
    <collision>
      <origin rpy="0 1.5708 0" xyz="-0.031 0 0.034"/>
      <geometry>
        <cylinder length="0.010" radius="0.011"/>
      </geometry>
    </collision>
    <collision>
      <origin rpy="0 0.7854 0" xyz="0.021 0 0.011"/>
      <geometry>
        <box size="0.027 0.018 0.010"/>
      </geometry>
    </collision>
    <collision>
      <origin rpy="0 -0.7854 0" xyz="-0.026 0 0.010"/>
      <geometry>
        <box size="0.027 0.018 0.010"/>
      </geometry>
    </collision>
  </link>
  <joint name="lh_WRJ2" type="revolute">
    <parent link="lh_forearm"/>
    <child link="lh_wrist"/>
    <origin rpy="3.14159 -0.1396263 3.14159" xyz="-0.013287 0 -0.248456"/>
    <axis xyz="0 1 0"/>
    <limit effort="10" lower="-0.5235987755982988" upper="0.17453292519943295" velocity="2.0"/>
    <dynamics damping="0.1"/>
  </joint>
  <link name="lh_palm">
    <inertial>
      <origin rpy="0 0 0" xyz="0 0 0.035"/>
      <mass value="0.3"/>
      <inertia ixx="0.0003581" ixy="0.0" ixz="0.0" iyy="0.0005287" iyz="0.0" izz="0.000191"/>
    </inertial>
    <visual>
      <origin rpy="0 0 0" xyz="0 0 0"/>
      <geometry>
        <mesh filename="C:/Projects/RevExBot/RevEx_Phase1_Hardware/mechanical/meshes/lh_palm_E3M5.stl"/>
      </geometry>
      <material name="Grey"/>
    </visual>
    <collision>
      <origin rpy="0 0 0" xyz="-0.011 0.0085 0.038"/>
      <geometry>
        <box size="0.062 0.007 0.098"/>
      </geometry>
    </collision>
    <collision>
      <origin rpy="0 0 0" xyz="0.002 -0.0035 0.038"/>
      <geometry>
        <box size="0.036 0.017 0.098"/>
      </geometry>
    </collision>
    <collision>
      <origin rpy="0 0 0" xyz="-0.029 -0.0035 0.082"/>
      <geometry>
        <box size="0.026 0.017 0.010"/>
      </geometry>
    </collision>
    <collision>
      <origin rpy="-0.2 0 -0.25" xyz="-0.0265 -0.001 0.070"/>
      <geometry>
        <box size="0.026 0.014 0.018"/>
      </geometry>
    </collision>
    <collision>
      <origin rpy="0 0 0" xyz="-0.0315 -0.0085 0.001"/>
      <geometry>
        <box size="0.021 0.027 0.024"/>
      </geometry>
    </collision>
    <collision>
      <origin rpy="0 0 0.48" xyz="-0.0125 -0.015 0.009"/>
      <geometry>
        <box size="0.022 0.005 0.040"/>
      </geometry>
    </collision>
    <collision>
      <origin rpy="0 0 0" xyz="-0.011 0 0.089"/>
      <geometry>
        <box size="0.018 0.024 0.004"/>
      </geometry>
    </collision>
    <collision>
      <origin rpy="0 0 0" xyz="0.03 0 0.009"/>
      <geometry>
        <box size="0.020 0.024 0.040"/>
      </geometry>
    </collision>
  </link>
  <joint name="lh_WRJ1" type="revolute">
    <parent link="lh_wrist"/>
    <child link="lh_palm"/>
    <origin rpy="0 0 0" xyz="0 0 0.034"/>
    <axis xyz="1 0 0"/>
    <limit effort="30" lower="-0.6981317007977318" upper="0.4886921905584123" velocity="2.0"/>
    <dynamics damping="0.1"/>
  </joint>
  <link name="lh_manipulator"/>
  <joint name="lh_ee_fixed_joint" type="fixed">
    <parent link="lh_palm"/>
    <child link="lh_manipulator"/>
    <origin rpy="0.0 0.0 0.0" xyz="0.0 0.0 0.05"/>
  </joint>
  <link name="lh_imu"/>
  <joint name="lh_palm_to_imu" type="fixed">
    <parent link="lh_palm"/>
    <child link="lh_imu"/>
    <origin rpy="1.5707963 3.141592 0.0" xyz="-0.01785 0.00765 0.049125"/>
  </joint>
  <link name="lh_ffknuckle">
    <inertial>
      <origin rpy="0 0 0" xyz="0 0 0"/>
      <mass value="0.008"/>
      <inertia ixx="0.00000026" ixy="0.0" ixz="0.0" iyy="0.00000026" iyz="0.0" izz="0.00000032"/>
    </inertial>
    <visual>
      <origin rpy="0 0 0" xyz="0 0 0.0005"/>
      <geometry>
        <mesh filename="C:/Projects/RevExBot/RevEx_Phase1_Hardware/mechanical/meshes/lh_f_knuckle_E3M5.stl"/>
      </geometry>
      <material name="LightGrey"/>
    </visual>
    <collision>
      <origin rpy="0 1.5708 0" xyz="0 0 0"/>
      <geometry>
        <cylinder length="0.014" radius="0.007"/>
      </geometry>
    </collision>
  </link>
  <joint name="lh_FFJ4" type="revolute">
    <parent link="lh_palm"/>
    <child link="lh_ffknuckle"/>
    <origin rpy="0 0 0" xyz="-0.033 0 0.095"/>
    <axis xyz="0 -1 0"/>
    <limit effort="2" lower="-0.3490658503988659" upper="0.3490658503988659" velocity="2.0"/>
    <dynamics damping="0.1"/>
  </joint>
  <link name="lh_ffproximal">
    <inertial>
      <mass value="0.030"/>
      <origin xyz="0 0 0.0225"/>
      <inertia ixx="0.0000098" ixy="0.0" ixz="0.0" iyy="0.00001" iyz="0.0" izz="0.0000018"/>
    </inertial>
    <visual>
      <origin rpy="0 0 0" xyz="0 0 0"/>
      <geometry>
        <mesh filename="C:/Projects/RevExBot/RevEx_Phase1_Hardware/mechanical/meshes/lh_f_proximal_E3M5.stl"/>
      </geometry>
      <material name="Grey"/>
    </visual>
    <collision>
      <origin rpy="0 0 0" xyz="0 0 0.025"/>
      <geometry>
        <cylinder length="0.040" radius="0.007"/>
      </geometry>
    </collision>
  </link>
  <joint name="lh_FFJ3" type="revolute">
    <parent link="lh_ffknuckle"/>
    <child link="lh_ffproximal"/>
    <origin rpy="0 0 0" xyz="0 0 0"/>
    <axis xyz="1 0 0"/>
    <limit effort="2" lower="-0.2617993877991494" upper="1.5707963267948966" velocity="2.0"/>
    <dynamics damping="0.1"/>
  </joint>
  <link name="lh_ffmiddle">
    <inertial>
      <origin rpy="0 0 0" xyz="0 0 0.0125"/>
      <mass value="0.017"/>
      <inertia ixx="0.0000026" ixy="0.0" ixz="0.0" iyy="0.0000027" iyz="0.0" izz="0.00000087"/>
    </inertial>
    <visual>
      <origin rpy="0 0 0" xyz="0 0 0"/>
      <geometry>
        <mesh filename="C:/Projects/RevExBot/RevEx_Phase1_Hardware/mechanical/meshes/lh_f_middle_E3M5.stl"/>
      </geometry>
      <material name="Grey"/>
    </visual>
    <collision>
      <origin rpy="0 0 0" xyz="0 0 0.0125"/>
      <geometry>
        <cylinder length="0.025" radius="0.007"/>
      </geometry>
    </collision>
    <collision>
      <origin rpy="0 0 0" xyz="0 0 0.0"/>
      <geometry>
        <sphere radius="0.007"/>
      </geometry>
    </collision>
    <collision>
      <origin rpy="0 0 0" xyz="0 0 0.025"/>
      <geometry>
        <sphere radius="0.007"/>
      </geometry>
    </collision>
  </link>
  <joint name="lh_FFJ2" type="revolute">
    <parent link="lh_ffproximal"/>
    <child link="lh_ffmiddle"/>
    <origin rpy="0 0 0" xyz="0 0 0.045"/>
    <axis xyz="1 0 0"/>
    <limit effort="2" lower="0" upper="1.5707963267948966" velocity="2.0"/>
    <dynamics damping="0.1"/>
  </joint>
  <link name="lh_ffdistal">
    <inertial>
      <mass value="0.012"/>
      <origin xyz="0 0 0.012"/>
      <inertia ixx="0.00000094" ixy="0.0" ixz="0.0" iyy="0.0000011" iyz="0.0" izz="0.00000053"/>
    </inertial>
    <visual>
      <origin rpy="0 0 0" xyz="0 0 0"/>
      <geometry>
        <mesh filename="C:/Projects/RevExBot/RevEx_Phase1_Hardware/mechanical/meshes/lh_f_distal_pst.stl"/>
      </geometry>
    </visual>
    <collision>
      <origin rpy="0 0 0" xyz="0 0 0"/>
      <geometry>
        <mesh filename="C:/Projects/RevExBot/RevEx_Phase1_Hardware/mechanical/meshes/lh_f_distal_pst.stl"/>
      </geometry>
    </collision>
  </link>
  <joint name="lh_FFJ1" type="revolute">
    <parent link="lh_ffmiddle"/>
    <child link="lh_ffdistal"/>
    <origin rpy="0 0 0" xyz="0 0 0.025"/>
    <axis xyz="1 0 0"/>
    <limit effort="2" lower="0" upper="1.5707963267948966" velocity="2.0"/>
    <dynamics damping="0.1"/>
  </joint>
  <link name="lh_fftip">
    <inertial>
      <mass value="0.001"/>
      <inertia ixx="0.00001" ixy="0.0" ixz="0.0" iyy="0.00001" iyz="0.0" izz="0.00001"/>
    </inertial>
  </link>
  <joint name="lh_FFtip" type="fixed">
    <parent link="lh_ffdistal"/>
    <child link="lh_fftip"/>
    <origin rpy="0 0 0" xyz="0 0 0.026"/>
  </joint>
  <link name="lh_mfknuckle">
    <inertial>
      <origin rpy="0 0 0" xyz="0 0 0"/>
      <mass value="0.008"/>
      <inertia ixx="0.00000026" ixy="0.0" ixz="0.0" iyy="0.00000026" iyz="0.0" izz="0.00000032"/>
    </inertial>
    <visual>
      <origin rpy="0 0 0" xyz="0 0 0.0005"/>
      <geometry>
        <mesh filename="C:/Projects/RevExBot/RevEx_Phase1_Hardware/mechanical/meshes/lh_f_knuckle_E3M5.stl"/>
      </geometry>
      <material name="LightGrey"/>
    </visual>
    <collision>
      <origin rpy="0 1.5708 0" xyz="0 0 0"/>
      <geometry>
        <cylinder length="0.014" radius="0.007"/>
      </geometry>
    </collision>
  </link>
  <joint name="lh_MFJ4" type="revolute">
    <parent link="lh_palm"/>
    <child link="lh_mfknuckle"/>
    <origin rpy="0 0 0" xyz="-0.011 0 0.099"/>
    <axis xyz="0 -1 0"/>
    <limit effort="2" lower="-0.3490658503988659" upper="0.3490658503988659" velocity="2.0"/>
    <dynamics damping="0.1"/>
  </joint>
  <link name="lh_mfproximal">
    <inertial>
      <mass value="0.030"/>
      <origin xyz="0 0 0.0225"/>
      <inertia ixx="0.0000098" ixy="0.0" ixz="0.0" iyy="0.00001" iyz="0.0" izz="0.0000018"/>
    </inertial>
    <visual>
      <origin rpy="0 0 0" xyz="0 0 0"/>
      <geometry>
        <mesh filename="C:/Projects/RevExBot/RevEx_Phase1_Hardware/mechanical/meshes/lh_f_proximal_E3M5.stl"/>
      </geometry>
      <material name="Grey"/>
    </visual>
    <collision>
      <origin rpy="0 0 0" xyz="0 0 0.025"/>
      <geometry>
        <cylinder length="0.040" radius="0.007"/>
      </geometry>
    </collision>
  </link>
  <joint name="lh_MFJ3" type="revolute">
    <parent link="lh_mfknuckle"/>
    <child link="lh_mfproximal"/>
    <origin rpy="0 0 0" xyz="0 0 0"/>
    <axis xyz="1 0 0"/>
    <limit effort="2" lower="-0.2617993877991494" upper="1.5707963267948966" velocity="2.0"/>
    <dynamics damping="0.1"/>
  </joint>
  <link name="lh_mfmiddle">
    <inertial>
      <origin rpy="0 0 0" xyz="0 0 0.0125"/>
      <mass value="0.017"/>
      <inertia ixx="0.0000026" ixy="0.0" ixz="0.0" iyy="0.0000027" iyz="0.0" izz="0.00000087"/>
    </inertial>
    <visual>
      <origin rpy="0 0 0" xyz="0 0 0"/>
      <geometry>
        <mesh filename="C:/Projects/RevExBot/RevEx_Phase1_Hardware/mechanical/meshes/lh_f_middle_E3M5.stl"/>
      </geometry>
      <material name="Grey"/>
    </visual>
    <collision>
      <origin rpy="0 0 0" xyz="0 0 0.0125"/>
      <geometry>
        <cylinder length="0.025" radius="0.007"/>
      </geometry>
    </collision>
    <collision>
      <origin rpy="0 0 0" xyz="0 0 0.0"/>
      <geometry>
        <sphere radius="0.007"/>
      </geometry>
    </collision>
    <collision>
      <origin rpy="0 0 0" xyz="0 0 0.025"/>
      <geometry>
        <sphere radius="0.007"/>
      </geometry>
    </collision>
  </link>
  <joint name="lh_MFJ2" type="revolute">
    <parent link="lh_mfproximal"/>
    <child link="lh_mfmiddle"/>
    <origin rpy="0 0 0" xyz="0 0 0.045"/>
    <axis xyz="1 0 0"/>
    <limit effort="2" lower="0" upper="1.5707963267948966" velocity="2.0"/>
    <dynamics damping="0.1"/>
  </joint>
  <link name="lh_mfdistal">
    <inertial>
      <mass value="0.012"/>
      <origin xyz="0 0 0.012"/>
      <inertia ixx="0.00000094" ixy="0.0" ixz="0.0" iyy="0.0000011" iyz="0.0" izz="0.00000053"/>
    </inertial>
    <visual>
      <origin rpy="0 0 0" xyz="0 0 0"/>
      <geometry>
        <mesh filename="C:/Projects/RevExBot/RevEx_Phase1_Hardware/mechanical/meshes/lh_f_distal_pst.stl"/>
      </geometry>
    </visual>
    <collision>
      <origin rpy="0 0 0" xyz="0 0 0"/>
      <geometry>
        <mesh filename="C:/Projects/RevExBot/RevEx_Phase1_Hardware/mechanical/meshes/lh_f_distal_pst.stl"/>
      </geometry>
    </collision>
  </link>
  <joint name="lh_MFJ1" type="revolute">
    <parent link="lh_mfmiddle"/>
    <child link="lh_mfdistal"/>
    <origin rpy="0 0 0" xyz="0 0 0.025"/>
    <axis xyz="1 0 0"/>
    <limit effort="2" lower="0" upper="1.5707963267948966" velocity="2.0"/>
    <dynamics damping="0.1"/>
  </joint>
  <link name="lh_mftip">
    <inertial>
      <mass value="0.001"/>
      <inertia ixx="0.00001" ixy="0.0" ixz="0.0" iyy="0.00001" iyz="0.0" izz="0.00001"/>
    </inertial>
  </link>
  <joint name="lh_MFtip" type="fixed">
    <parent link="lh_mfdistal"/>
    <child link="lh_mftip"/>
    <origin rpy="0 0 0" xyz="0 0 0.026"/>
  </joint>
  <link name="lh_rfknuckle">
    <inertial>
      <origin rpy="0 0 0" xyz="0 0 0"/>
      <mass value="0.008"/>
      <inertia ixx="0.00000026" ixy="0.0" ixz="0.0" iyy="0.00000026" iyz="0.0" izz="0.00000032"/>
    </inertial>
    <visual>
      <origin rpy="0 0 0" xyz="0 0 0.0005"/>
      <geometry>
        <mesh filename="C:/Projects/RevExBot/RevEx_Phase1_Hardware/mechanical/meshes/lh_f_knuckle_E3M5.stl"/>
      </geometry>
      <material name="LightGrey"/>
    </visual>
    <collision>
      <origin rpy="0 1.5708 0" xyz="0 0 0"/>
      <geometry>
        <cylinder length="0.014" radius="0.007"/>
      </geometry>
    </collision>
  </link>
  <joint name="lh_RFJ4" type="revolute">
    <parent link="lh_palm"/>
    <child link="lh_rfknuckle"/>
    <origin rpy="0 0 0" xyz="0.011 0 0.095"/>
    <axis xyz="0 1 0"/>
    <limit effort="2" lower="-0.3490658503988659" upper="0.3490658503988659" velocity="2.0"/>
    <dynamics damping="0.1"/>
  </joint>
  <link name="lh_rfproximal">
    <inertial>
      <mass value="0.030"/>
      <origin xyz="0 0 0.0225"/>
      <inertia ixx="0.0000098" ixy="0.0" ixz="0.0" iyy="0.00001" iyz="0.0" izz="0.0000018"/>
    </inertial>
    <visual>
      <origin rpy="0 0 0" xyz="0 0 0"/>
      <geometry>
        <mesh filename="C:/Projects/RevExBot/RevEx_Phase1_Hardware/mechanical/meshes/lh_f_proximal_E3M5.stl"/>
      </geometry>
      <material name="Grey"/>
    </visual>
    <collision>
      <origin rpy="0 0 0" xyz="0 0 0.025"/>
      <geometry>
        <cylinder length="0.040" radius="0.007"/>
      </geometry>
    </collision>
  </link>
  <joint name="lh_RFJ3" type="revolute">
    <parent link="lh_rfknuckle"/>
    <child link="lh_rfproximal"/>
    <origin rpy="0 0 0" xyz="0 0 0"/>
    <axis xyz="1 0 0"/>
    <limit effort="2" lower="-0.2617993877991494" upper="1.5707963267948966" velocity="2.0"/>
    <dynamics damping="0.1"/>
  </joint>
  <link name="lh_rfmiddle">
    <inertial>
      <origin rpy="0 0 0" xyz="0 0 0.0125"/>
      <mass value="0.017"/>
      <inertia ixx="0.0000026" ixy="0.0" ixz="0.0" iyy="0.0000027" iyz="0.0" izz="0.00000087"/>
    </inertial>
    <visual>
      <origin rpy="0 0 0" xyz="0 0 0"/>
      <geometry>
        <mesh filename="C:/Projects/RevExBot/RevEx_Phase1_Hardware/mechanical/meshes/lh_f_middle_E3M5.stl"/>
      </geometry>
      <material name="Grey"/>
    </visual>
    <collision>
      <origin rpy="0 0 0" xyz="0 0 0.0125"/>
      <geometry>
        <cylinder length="0.025" radius="0.007"/>
      </geometry>
    </collision>
    <collision>
      <origin rpy="0 0 0" xyz="0 0 0.0"/>
      <geometry>
        <sphere radius="0.007"/>
      </geometry>
    </collision>
    <collision>
      <origin rpy="0 0 0" xyz="0 0 0.025"/>
      <geometry>
        <sphere radius="0.007"/>
      </geometry>
    </collision>
  </link>
  <joint name="lh_RFJ2" type="revolute">
    <parent link="lh_rfproximal"/>
    <child link="lh_rfmiddle"/>
    <origin rpy="0 0 0" xyz="0 0 0.045"/>
    <axis xyz="1 0 0"/>
    <limit effort="2" lower="0" upper="1.5707963267948966" velocity="2.0"/>
    <dynamics damping="0.1"/>
  </joint>
  <link name="lh_rfdistal">
    <inertial>
      <mass value="0.012"/>
      <origin xyz="0 0 0.012"/>
      <inertia ixx="0.00000094" ixy="0.0" ixz="0.0" iyy="0.0000011" iyz="0.0" izz="0.00000053"/>
    </inertial>
    <visual>
      <origin rpy="0 0 0" xyz="0 0 0"/>
      <geometry>
        <mesh filename="C:/Projects/RevExBot/RevEx_Phase1_Hardware/mechanical/meshes/lh_f_distal_pst.stl"/>
      </geometry>
    </visual>
    <collision>
      <origin rpy="0 0 0" xyz="0 0 0"/>
      <geometry>
        <mesh filename="C:/Projects/RevExBot/RevEx_Phase1_Hardware/mechanical/meshes/lh_f_distal_pst.stl"/>
      </geometry>
    </collision>
  </link>
  <joint name="lh_RFJ1" type="revolute">
    <parent link="lh_rfmiddle"/>
    <child link="lh_rfdistal"/>
    <origin rpy="0 0 0" xyz="0 0 0.025"/>
    <axis xyz="1 0 0"/>
    <limit effort="2" lower="0" upper="1.5707963267948966" velocity="2.0"/>
    <dynamics damping="0.1"/>
  </joint>
  <link name="lh_rftip">
    <inertial>
      <mass value="0.001"/>
      <inertia ixx="0.00001" ixy="0.0" ixz="0.0" iyy="0.00001" iyz="0.0" izz="0.00001"/>
    </inertial>
  </link>
  <joint name="lh_RFtip" type="fixed">
    <parent link="lh_rfdistal"/>
    <child link="lh_rftip"/>
    <origin rpy="0 0 0" xyz="0 0 0.026"/>
  </joint>
  <link name="lh_lfmetacarpal">
    <inertial>
      <origin rpy="0 -0.9599 0" xyz="-0.031748676 0 0.02235294"/>
      <mass value="0.030"/>
      <inertia ixx="0.0000145" ixy="0.0" ixz="0.0" iyy="0.00001638" iyz="0.0" izz="0.000004272"/>
    </inertial>
    <visual>
      <origin rpy="0 -0.9599 0" xyz="0 0 0"/>
      <geometry>
        <mesh filename="C:/Projects/RevExBot/RevEx_Phase1_Hardware/mechanical/meshes/lh_lf_metacarpal_E3M5.stl"/>
      </geometry>
      <material name="Grey"/>
    </visual>
    <collision>
      <origin rpy="0 -0.9599 0" xyz="-0.026986375 0 0.019"/>
      <geometry>
        <box size="0.018 0.024 0.040"/>
      </geometry>
    </collision>
  </link>
  <joint name="lh_LFJ5" type="revolute">
    <parent link="lh_palm"/>
    <child link="lh_lfmetacarpal"/>
    <origin rpy="0 0.9599 0" xyz="0.033 0 0.02071"/>
    <axis xyz="1 0 0"/>
    <limit effort="2" lower="0" upper="0.7853981633974483" velocity="2.0"/>
    <dynamics damping="0.1"/>
  </joint>
  <link name="lh_lfknuckle">
    <inertial>
      <origin rpy="0 0 0" xyz="0 0 0"/>
      <mass value="0.008"/>
      <inertia ixx="0.00000026" ixy="0.0" ixz="0.0" iyy="0.00000026" iyz="0.0" izz="0.00000032"/>
    </inertial>
    <visual>
      <origin rpy="0 0 0" xyz="0 0 0.0005"/>
      <geometry>
        <mesh filename="C:/Projects/RevExBot/RevEx_Phase1_Hardware/mechanical/meshes/lh_f_knuckle_E3M5.stl"/>
      </geometry>
      <material name="LightGrey"/>
    </visual>
    <collision>
      <origin rpy="0 1.5708 0" xyz="0 0 0"/>
      <geometry>
        <cylinder length="0.014" radius="0.007"/>
      </geometry>
    </collision>
  </link>
  <joint name="lh_LFJ4" type="revolute">
    <parent link="lh_lfmetacarpal"/>
    <child link="lh_lfknuckle"/>
    <origin rpy="0 -0.9599 0" xyz="-0.05397275 0 0.03779463"/>
    <axis xyz="0 1 0"/>
    <limit effort="2" lower="-0.3490658503988659" upper="0.3490658503988659" velocity="2.0"/>
    <dynamics damping="0.1"/>
  </joint>
  <link name="lh_lfknuckle">
    <inertial>
      <origin rpy="0 0 0" xyz="0 0 0"/>
      <mass value="0.008"/>
      <inertia ixx="0.00000026" ixy="0.0" ixz="0.0" iyy="0.00000026" iyz="0.0" izz="0.00000032"/>
    </inertial>
    <visual>
      <origin rpy="0 0 0" xyz="0 0 0.0005"/>
      <geometry>
        <mesh filename="C:/Projects/RevExBot/RevEx_Phase1_Hardware/mechanical/meshes/lh_f_knuckle_E3M5.stl"/>
      </geometry>
      <material name="LightGrey"/>
    </visual>
    <collision>
      <origin rpy="0 1.5708 0" xyz="0 0 0"/>
      <geometry>
        <cylinder length="0.014" radius="0.007"/>
      </geometry>
    </collision>
  </link>
  <link name="lh_lfproximal">
    <inertial>
      <mass value="0.030"/>
      <origin xyz="0 0 0.0225"/>
      <inertia ixx="0.0000098" ixy="0.0" ixz="0.0" iyy="0.00001" iyz="0.0" izz="0.0000018"/>
    </inertial>
    <visual>
      <origin rpy="0 0 0" xyz="0 0 0"/>
      <geometry>
        <mesh filename="C:/Projects/RevExBot/RevEx_Phase1_Hardware/mechanical/meshes/lh_f_proximal_E3M5.stl"/>
      </geometry>
      <material name="Grey"/>
    </visual>
    <collision>
      <origin rpy="0 0 0" xyz="0 0 0.025"/>
      <geometry>
        <cylinder length="0.040" radius="0.007"/>
      </geometry>
    </collision>
  </link>
  <joint name="lh_LFJ3" type="revolute">
    <parent link="lh_lfknuckle"/>
    <child link="lh_lfproximal"/>
    <origin rpy="0 0 0" xyz="0 0 0"/>
    <axis xyz="1 0 0"/>
    <limit effort="2" lower="-0.2617993877991494" upper="1.5707963267948966" velocity="2.0"/>
    <dynamics damping="0.1"/>
  </joint>
  <link name="lh_lfmiddle">
    <inertial>
      <origin rpy="0 0 0" xyz="0 0 0.0125"/>
      <mass value="0.017"/>
      <inertia ixx="0.0000026" ixy="0.0" ixz="0.0" iyy="0.0000027" iyz="0.0" izz="0.00000087"/>
    </inertial>
    <visual>
      <origin rpy="0 0 0" xyz="0 0 0"/>
      <geometry>
        <mesh filename="C:/Projects/RevExBot/RevEx_Phase1_Hardware/mechanical/meshes/lh_f_middle_E3M5.stl"/>
      </geometry>
      <material name="Grey"/>
    </visual>
    <collision>
      <origin rpy="0 0 0" xyz="0 0 0.0125"/>
      <geometry>
        <cylinder length="0.025" radius="0.007"/>
      </geometry>
    </collision>
    <collision>
      <origin rpy="0 0 0" xyz="0 0 0.0"/>
      <geometry>
        <sphere radius="0.007"/>
      </geometry>
    </collision>
    <collision>
      <origin rpy="0 0 0" xyz="0 0 0.025"/>
      <geometry>
        <sphere radius="0.007"/>
      </geometry>
    </collision>
  </link>
  <joint name="lh_LFJ2" type="revolute">
    <parent link="lh_lfproximal"/>
    <child link="lh_lfmiddle"/>
    <origin rpy="0 0 0" xyz="0 0 0.045"/>
    <axis xyz="1 0 0"/>
    <limit effort="2" lower="0" upper="1.5707963267948966" velocity="2.0"/>
    <dynamics damping="0.1"/>
  </joint>
  <link name="lh_lfdistal">
    <inertial>
      <mass value="0.012"/>
      <origin xyz="0 0 0.012"/>
      <inertia ixx="0.00000094" ixy="0.0" ixz="0.0" iyy="0.0000011" iyz="0.0" izz="0.00000053"/>
    </inertial>
    <visual>
      <origin rpy="0 0 0" xyz="0 0 0"/>
      <geometry>
        <mesh filename="C:/Projects/RevExBot/RevEx_Phase1_Hardware/mechanical/meshes/lh_f_distal_pst.stl"/>
      </geometry>
    </visual>
    <collision>
      <origin rpy="0 0 0" xyz="0 0 0"/>
      <geometry>
        <mesh filename="C:/Projects/RevExBot/RevEx_Phase1_Hardware/mechanical/meshes/lh_f_distal_pst.stl"/>
      </geometry>
    </collision>
  </link>
  <joint name="lh_LFJ1" type="revolute">
    <parent link="lh_lfmiddle"/>
    <child link="lh_lfdistal"/>
    <origin rpy="0 0 0" xyz="0 0 0.025"/>
    <axis xyz="1 0 0"/>
    <limit effort="2" lower="0" upper="1.5707963267948966" velocity="2.0"/>
    <dynamics damping="0.1"/>
  </joint>
  <link name="lh_lftip">
    <inertial>
      <mass value="0.001"/>
      <inertia ixx="0.00001" ixy="0.0" ixz="0.0" iyy="0.00001" iyz="0.0" izz="0.00001"/>
    </inertial>
  </link>
  <joint name="lh_LFtip" type="fixed">
    <parent link="lh_lfdistal"/>
    <child link="lh_lftip"/>
    <origin rpy="0 0 0" xyz="0 0 0.026"/>
  </joint>
  <link name="lh_thbase">
    <inertial>
      <mass value="0.010"/>
      <origin rpy="0 0 0" xyz="0 0 0"/>
      <inertia ixx="0.00000016" ixy="0.0" ixz="0.0" iyy="0.00000016" iyz="0.0" izz="0.00000016"/>
    </inertial>
    <visual>
      <origin rpy="0 0 0" xyz="0 0 0"/>
      <geometry>
        <box size="0.001 0.001 0.001"/>
      </geometry>
      <material name="shadow_thbase_material">
        <color rgba="0.5 0.5 0.5 1.0"/>
      </material>
    </visual>
    <collision>
      <origin rpy="0 0 0" xyz="0 0 0"/>
      <geometry>
        <sphere radius="0.011"/>
      </geometry>
    </collision>
  </link>
  <joint name="lh_THJ5" type="revolute">
    <parent link="lh_palm"/>
    <child link="lh_thbase"/>
    <origin rpy="-0.7853981633974483 0 1.5707963267948966" xyz="-0.034 -0.00858 0.029"/>
    <axis xyz="0 0 -1"/>
    <limit effort="5.0" lower="-1.0471975511965976" upper="1.0471975511965976" velocity="4.0"/>
    <dynamics damping="0.2"/>
  </joint>
  <link name="lh_thproximal">
    <inertial>
      <mass value="0.040"/>
      <origin rpy="0 0 0" xyz="0 0 0.019"/>
      <inertia ixx="0.0000136" ixy="0.0" ixz="0.0" iyy="0.0000136" iyz="0.0" izz="0.00000313"/>
    </inertial>
    <visual>
      <origin rpy="0 0 -1.5707963267948966" xyz="0 0 0"/>
      <geometry>
        <mesh filename="C:/Projects/RevExBot/RevEx_Phase1_Hardware/mechanical/meshes/lh_th_proximal_E3M5.stl"/>
      </geometry>
      <material name="shadow_thproximal_material">
        <color rgba="0.2 0.2 0.2 1.0"/>
      </material>
    </visual>
    <collision>
      <origin rpy="0 0 0" xyz="0 0 0.020"/>
      <geometry>
        <cylinder length="0.018" radius="0.012"/>
      </geometry>
    </collision>
  </link>
  <joint name="lh_THJ4" type="revolute">
    <parent link="lh_thbase"/>
    <child link="lh_thproximal"/>
    <origin rpy="0 0 0" xyz="0 0 0"/>
    <axis xyz="0 1 0"/>
    <limit effort="3" lower="0.0" upper="1.2217304763960306" velocity="4.0"/>
    <dynamics damping="0.2"/>
  </joint>
  <link name="lh_thhub">
    <inertial>
      <mass value="0.005"/>
      <origin rpy="0 0 0" xyz="0 0 0"/>
      <inertia ixx="0.000001" ixy="0.0" ixz="0.0" iyy="0.000001" iyz="0.0" izz="0.0000003"/>
    </inertial>
    <visual>
      <origin rpy="0 0 0" xyz="0 0 0"/>
      <geometry>
        <box size="0.001 0.001 0.001"/>
      </geometry>
      <material name="shadow_thhub_material">
        <color rgba="0.7 0.7 0.7 1.0"/>
      </material>
    </visual>
    <collision>
      <origin rpy="0 0 0" xyz="0 0 0"/>
      <geometry>
        <sphere radius="0.010"/>
      </geometry>
    </collision>
  </link>
  <joint name="lh_THJ3" type="revolute">
    <parent link="lh_thproximal"/>
    <child link="lh_thhub"/>
    <origin rpy="0 0 0" xyz="0 0 0.038"/>
    <axis xyz="0 1 0"/>
    <limit effort="2.0" lower="-0.20943951023931953" upper="0.20943951023931953" velocity="4.0"/>
    <dynamics damping="0.2"/>
  </joint>
  <link name="lh_thmiddle">
    <inertial>
      <mass value="0.020"/>
      <origin rpy="0 0 0" xyz="0 0 0.016"/>
      <inertia ixx="0.0000051" ixy="0.0" ixz="0.0" iyy="0.0000051" iyz="0.0" izz="0.00000121"/>
    </inertial>
    <visual>
      <origin rpy="0 0 -1.5707963267948966" xyz="0 0 0"/>
      <geometry>
        <mesh filename="C:/Projects/RevExBot/RevEx_Phase1_Hardware/mechanical/meshes/lh_th_middle_E3M5.stl"/>
      </geometry>
      <material name="shadow_thmiddle_material">
        <color rgba="0.2 0.2 0.2 1.0"/>
      </material>
    </visual>
    <collision>
      <origin rpy="0 0 0" xyz="0 0 0.012"/>
      <geometry>
        <cylinder length="0.018" radius="0.011"/>
      </geometry>
    </collision>
    <collision>
      <origin rpy="0 0 0" xyz="0 0 0.019"/>
      <geometry>
        <sphere radius="0.011"/>
      </geometry>
    </collision>
    <collision>
      <origin rpy="0 1.5708 0" xyz="0 0 0.032"/>
      <geometry>
        <cylinder length="0.014" radius="0.010"/>
      </geometry>
    </collision>
  </link>
  <joint name="lh_THJ2" type="revolute">
    <parent link="lh_thhub"/>
    <child link="lh_thmiddle"/>
    <origin rpy="0 0 0" xyz="0 0 0"/>
    <axis xyz="1 0 0"/>
    <limit effort="2.0" lower="-0.6981317007977318" upper="0.6981317007977318" velocity="2.0"/>
    <dynamics damping="0.1"/>
  </joint>
  <link name="lh_thdistal">
    <inertial>
      <mass value="0.016"/>
      <origin rpy="0 0 0" xyz="0 0 0.01375"/>
      <inertia ixx="0.0000021" ixy="0.0" ixz="0.0" iyy="0.0000022" iyz="0.0" izz="0.000001"/>
    </inertial>
    <visual>
      <origin rpy="0 0 0" xyz="0 0 0"/>
      <geometry>
        <mesh filename="C:/Projects/RevExBot/RevEx_Phase1_Hardware/mechanical/meshes/lh_th_distal_pst.stl"/>
      </geometry>
      <material name="shadow_thmiddle_material">
        <color rgba="0.2 0.2 0.2 1.0"/>
      </material>
    </visual>
    <collision>
      <origin rpy="0 0 0" xyz="0 0 0"/>
      <geometry>
        <mesh filename="C:/Projects/RevExBot/RevEx_Phase1_Hardware/mechanical/meshes/lh_th_distal_pst.stl"/>
      </geometry>
    </collision>
  </link>
  <joint name="lh_THJ1" type="revolute">
    <parent link="lh_thmiddle"/>
    <child link="lh_thdistal"/>
    <origin rpy="0 0 0" xyz="0 0 0.032"/>
    <axis xyz="1 0 0"/>
    <limit effort="1.0" lower="-0.2617993877991494" upper="1.5707963267948966" velocity="4.0"/>
    <dynamics damping="0.2"/>
  </joint>
  <link name="lh_thtip">
    <inertial>
      <mass value="0.001"/>
      <inertia ixx="0.00001" ixy="0.0" ixz="0.0" iyy="0.00001" iyz="0.0" izz="0.00001"/>
    </inertial>
  </link>
  <joint name="lh_thtip" type="fixed">
    <parent link="lh_thdistal"/>
    <child link="lh_thtip"/>
    <origin rpy="0 0 0" xyz="0 0 0.0275"/>
  </joint>
  <joint name="left_elbow_to_forearm_glue" type="fixed">
    <parent link="left_elbow_link"/>
    <child link="lh_forearm"/>
    <origin rpy="0 -0.1396263 0" xyz="0 0 0"/>
  </joint>
</robot>
